Workbook

Sheet KCD-BIDANG
A1: DAFTAR MUTASI BARANG HABIS PAKAI TAHUN 2025
A2: ='REKAP PER KODERING&KENDALI'!AQ6 -> CABANG PENDIDIKAN WILAYAH X
N3: JANUARI | Z3: FEBRUARI | AL3: MARET | AX3: APRIL | BJ3: MEI | BV3: JUNI | CH3: JULI | CT3: AGUSTUS | DF3: SEPTEMBER | DR3: OKTOBER | ED3: NOVEMBER | EP3: DESEMBER | FE3: 48077787 | JB3: =SUBTOTAL(9,JB19:JB174) -> 199015533 | JF3: =SUBTOTAL(9,JF19:JF174) -> 198679952 | JJ3: =SUBTOTAL(9,JJ19:JJ174) -> 10636931 | JK3: =SUBTOTAL(9,JK19:JK174) -> 0
A4: NO | B4: PEMEGANG BARANG | C4: BARANG PERSEDIAAN | F4: WAJIB DIISI | J4: SALDO AWAL JANUARI 2025 | N4: MUTASI JANUARI 2025 | V4: SALDO 31 JANUARI 2025 | Z4: MUTASI FEBRUARI 2025 | AH4: SALDO 28 FEBRUARI 2025 | AL4: MUTASI MARET 2025 | AT4: SALDO 31 MARET 2025 | AX4: MUTASI APRIL 2025 | BF4: SALDO 30 APRIL 2025 | BJ4: MUTASI MEI 2025 | BR4: SALDO 31 MEI 2025 | BV4: MUTASI JUNI 2025 | CD4: SALDO 30 JUNI 2025 | CH4: MUTASI JULI 2025 | CP4: SALDO 31 JULI 2025 | CT4: MUTASI AGUSTUS 2025 | DB4: SALDO 31 AGUSTUS 2025 | DF4: MUTASI SEPTEMBER 2025 | DN4: SALDO 30 SEPTEMBER 2025 | DR4: MUTASI OKTOBER 2025 | DZ4: SALDO 31 OKTOBER 2025 | ED4: MUTASI NOVEMBER 2025 | EL4: SALDO 30 NOVEMBER 2025 | EP4: MUTASI DESEMBER 2025 | EX4: SALDO 31 DESEMBER 2025 | FB4: MUTASI MARET 2025 | FJ4: SALDO 31 MARET 2025 | FN4: MUTASI JUNI 2025 | FV4: SALDO 31 JUNI 2025 | FZ4: MUTASI SEMESTER 1 2025 | GH4: SALDO SEMESTER 1 2025 | GM4: MUTASI JULI, AGUSTUS DAN SEPTEMBER 2025 | GU4: SALDO TW III 2025 | GZ4: MUTASI TW III 2025 | HH4: SALDO s.d September 2025 | HL4: KAPITALISASI | HM4: ROUNDUP | IF4: ROUNDUP | IY4: MUTASI S.D OKTOBER 2025 | JG4: SALDO s.d OKTOBER 2025 | JK4: KAPITALISASI
N5: PENAMBAHAN | R5: PENGURANGAN | Z5: PENAMBAHAN | AD5: PENGURANGAN | AL5: PENAMBAHAN | AP5: PENGURANGAN | AX5: PENAMBAHAN | BB5: PENGURANGAN | BJ5: PENAMBAHAN | BN5: PENGURANGAN | BV5: PENAMBAHAN | BZ5: PENGURANGAN | CH5: PENAMBAHAN | CL5: PENGURANGAN | CT5: PENAMBAHAN | CX5: PENGURANGAN | DF5: PENAMBAHAN | DJ5: PENGURANGAN | DR5: PENAMBAHAN | DV5: PENGURANGAN | ED5: PENAMBAHAN | EH5: PENGURANGAN | EP5: PENAMBAHAN | ET5: PENGURANGAN | FB5: PENAMBAHAN | FF5: PENGURANGAN | FN5: PENAMBAHAN | FR5: PENGURANGAN | FZ5: PENAMBAHAN | GD5: PENGURANGAN | GM5: PENAMBAHAN | GQ5: PENGURANGAN | GZ5: PENAMBAHAN | HD5: PENGURANGAN | HM5: PENAMBAHAN | HS5: PENGURANGAN | HY5: SALDO | IF5: PENAMBAHAN | IL5: PENGURANGAN | IR5: SALDO | IY5: PENAMBAHAN | JC5: PENGURANGAN
C6: KODE REKENING | E6: NAMA BARANG | F6: MERK Jika tidak ada isi dengan CV/PT | G6: NO TBP/FAKTUR/ KWITANSI | H6: NO BAST | I6: Tanggal/Bulan/Tahun BAST | J6: VOLUME | K6: SATUAN | L6: HARGA SATUAN | M6: JUMLAH (Rp) | N6: VOLUME | O6: SATUAN | P6: HARGA SATUAN | Q6: JUMLAH (Rp) | R6: VOLUME | S6: SATUAN | T6: HARGA SATUAN | U6: JUMLAH (Rp) | V6: VOLUME | W6: SATUAN | X6: HARGA SATUAN | Y6: JUMLAH (Rp) | Z6: VOLUME | AA6: SATUAN | AB6: HARGA SATUAN | AC6: JUMLAH (Rp) | AD6: VOLUME | AE6: SATUAN | AF6: HARGA SATUAN | AG6: JUMLAH (Rp) | AH6: VOLUME | AI6: SATUAN | AJ6: HARGA SATUAN | AK6: JUMLAH (Rp) | AL6: VOLUME | AM6: SATUAN | AN6: HARGA SATUAN | AO6: JUMLAH (Rp) | AP6: VOLUME | AQ6: SATUAN | AR6: HARGA SATUAN | AS6: JUMLAH (Rp) | AT6: VOLUME | AU6: SATUAN | AV6: HARGA SATUAN | AW6: JUMLAH (Rp) | AX6: VOLUME | AY6: SATUAN | AZ6: HARGA SATUAN | BA6: JUMLAH (Rp) | BB6: VOLUME | BC6: SATUAN | BD6: HARGA SATUAN | BE6: JUMLAH (Rp) | BF6: VOLUME | BG6: SATUAN | BH6: HARGA SATUAN | BI6: JUMLAH (Rp) | BJ6: VOLUME | BK6: SATUAN | BL6: HARGA SATUAN | BM6: JUMLAH (Rp) | BN6: VOLUME | BO6: SATUAN | BP6: HARGA SATUAN | BQ6: JUMLAH (Rp) | BR6: VOLUME | BS6: SATUAN | BT6: HARGA SATUAN | BU6: JUMLAH (Rp) | BV6: VOLUME | BW6: SATUAN | BX6: HARGA SATUAN | BY6: JUMLAH (Rp) | BZ6: VOLUME | CA6: SATUAN | CB6: HARGA SATUAN | CC6: JUMLAH (Rp) | CD6: VOLUME | CE6: SATUAN | CF6: HARGA SATUAN | CG6: JUMLAH (Rp) | CH6: VOLUME | CI6: SATUAN | CJ6: HARGA SATUAN | CK6: JUMLAH (Rp) | CL6: VOLUME | CM6: SATUAN | CN6: HARGA SATUAN | CO6: JUMLAH (Rp) | CP6: VOLUME | CQ6: SATUAN | CR6: HARGA SATUAN | CS6: JUMLAH (Rp) | CT6: VOLUME | CU6: SATUAN | CV6: HARGA SATUAN | CW6: JUMLAH (Rp) | CX6: VOLUME | CY6: SATUAN | CZ6: HARGA SATUAN | DA6: JUMLAH (Rp) | DB6: VOLUME | DC6: SATUAN | DD6: HARGA SATUAN | DE6: JUMLAH (Rp) | DF6: VOLUME | DG6: SATUAN | DH6: HARGA SATUAN | DI6: JUMLAH (Rp) | DJ6: VOLUME | DK6: SATUAN | DL6: HARGA SATUAN | DM6: JUMLAH (Rp) | DN6: VOLUME | DO6: SATUAN | DP6: HARGA SATUAN | DQ6: JUMLAH (Rp) | DR6: VOLUME | DS6: SATUAN | DT6: HARGA SATUAN | DU6: JUMLAH (Rp) | DV6: VOLUME | DW6: SATUAN | DX6: HARGA SATUAN | DY6: JUMLAH (Rp) | DZ6: VOLUME | EA6: SATUAN | EB6: HARGA SATUAN | EC6: JUMLAH (Rp) | ED6: VOLUME | EE6: SATUAN | EF6: HARGA SATUAN | EG6: JUMLAH (Rp) | EH6: VOLUME | EI6: SATUAN | EJ6: HARGA SATUAN | EK6: JUMLAH (Rp) | EL6: VOLUME | EM6: SATUAN | EN6: HARGA SATUAN | EO6: JUMLAH (Rp) | EP6: VOLUME | EQ6: SATUAN | ER6: HARGA SATUAN | ES6: JUMLAH (Rp) | ET6: VOLUME | EU6: SATUAN | EV6: HARGA SATUAN | EW6: JUMLAH (Rp) | EX6: VOLUME | EY6: SATUAN | EZ6: HARGA SATUAN | FA6: JUMLAH (Rp) | FB6: VOLUME | FC6: SATUAN | FD6: HARGA SATUAN | FE6: JUMLAH (Rp) | FF6: VOLUME | FG6: SATUAN | FH6: HARGA SATUAN | FI6: JUMLAH (Rp) | FJ6: VOLUME | FK6: SATUAN | FL6: HARGA SATUAN | FM6: JUMLAH (Rp) | FN6: VOLUME | FO6: SATUAN | FP6: HARGA SATUAN | FQ6: JUMLAH (Rp) | FR6: VOLUME | FS6: SATUAN | FT6: HARGA SATUAN | FU6: JUMLAH (Rp) | FV6: VOLUME | FW6: SATUAN | FX6: HARGA SATUAN | FY6: JUMLAH (Rp) | FZ6: VOLUME | GA6: SATUAN | GB6: HARGA SATUAN | GC6: JUMLAH (Rp) | GD6: VOLUME | GE6: SATUAN | GF6: HARGA SATUAN | GG6: JUMLAH (Rp) | GH6: VOLUME | GI6: SATUAN | GJ6: HARGA SATUAN | GK6: JUMLAH (Rp) | GM6: VOLUME | GN6: SATUAN | GO6: HARGA SATUAN | GP6: JUMLAH (Rp) | GQ6: VOLUME | GR6: SATUAN | GS6: HARGA SATUAN | GT6: JUMLAH (Rp) | GU6: VOLUME | GV6: SATUAN | GW6: HARGA SATUAN | GX6: JUMLAH (Rp) | GZ6: VOLUME | HA6: SATUAN | HB6: HARGA SATUAN | HC6: JUMLAH (Rp) | HD6: VOLUME | HE6: SATUAN | HF6: HARGA SATUAN | HG6: JUMLAH (Rp) | HH6: VOLUME | HI6: SATUAN | HJ6: HARGA SATUAN | HK6: JUMLAH (Rp) | HM6: VOLUME | HN6: SELISIH | HO6: HARGA SATUAN | HP6: SELISIH | HQ6: JUMLAH (Rp) | HR6: SELISIH | HS6: VOLUME | HT6: SELISIH | HU6: HARGA SATUAN | HV6: SELISIH | HW6: JUMLAH (Rp) | HX6: SELISIH | HY6: VOLUME | HZ6: SELISIH | IA6: HARGA SATUAN | IB6: SELISIH | IC6: JUMLAH (Rp) | ID6: SELISIH | IF6: VOLUME | IG6: SELISIH | IH6: HARGA SATUAN | II6: SELISIH | IJ6: JUMLAH (Rp) | IK6: SELISIH | IL6: VOLUME | IM6: SELISIH | IN6: HARGA SATUAN | IO6: SELISIH | IP6: JUMLAH (Rp) | IQ6: SELISIH | IR6: VOLUME | IS6: SELISIH | IT6: HARGA SATUAN | IU6: SELISIH | IV6: JUMLAH (Rp) | IW6: SELISIH | IY6: VOLUME | IZ6: SATUAN | JA6: HARGA SATUAN | JB6: JUMLAH (Rp) | JC6: VOLUME | JD6: SATUAN | JE6: HARGA SATUAN | JF6: JUMLAH (Rp) | JG6: VOLUME | JH6: SATUAN | JI6: HARGA SATUAN | JJ6: JUMLAH (Rp)
A7: 1 | B7: 2 | C7: 3 | D7: 4 | E7: 5 | J7: 6 | K7: 7 | L7: 8 | M7: 9 = (6x8) | N7: 10 | O7: 11 | P7: 12 | Q7: 13 = (10x12) | R7: 14 | S7: 15 | T7: 16 | U7: 17 = (14x16) | V7: 18 | W7: 19 | X7: 20 | Y7: 21 = (18x20) | Z7: 10 | AA7: 11 | AB7: 12 | AC7: 13 = (10x12) | AD7: 14 | AE7: 15 | AF7: 16 | AG7: 17 = (14x16) | AH7: 18 | AI7: 19 | AJ7: 20 | AK7: 21 = (18x20) | AL7: 10 | AM7: 11 | AN7: 12 | AO7: 13 = (10x12) | AP7: 14 | AQ7: 15 | AR7: 16 | AS7: 17 = (14x16) | AT7: 18 | AU7: 19 | AV7: 20 | AW7: 21 = (18x20) | AX7: 10 | AY7: 11 | AZ7: 12 | BA7: 13 = (10x12) | BB7: 14 | BC7: 15 | BD7: 16 | BE7: 17 = (14x16) | BF7: 18 | BG7: 19 | BH7: 20 | BI7: 21 = (18x20) | BJ7: 10 | BK7: 11 | BL7: 12 | BM7: 13 = (10x12) | BN7: 14 | BO7: 15 | BP7: 16 | BQ7: 17 = (14x16) | BR7: 18 | BS7: 19 | BT7: 20 | BU7: 21 = (18x20) | BV7: 10 | BW7: 11 | BX7: 12 | BY7: 13 = (10x12) | BZ7: 14 | CA7: 15 | CB7: 16 | CC7: 17 = (14x16) | CD7: 18 | CE7: 19 | CF7: 20 | CG7: 21 = (18x20) | CH7: 10 | CI7: 11 | CJ7: 12 | CK7: 13 = (10x12) | CL7: 14 | CM7: 15 | CN7: 16 | CO7: 17 = (14x16) | CP7: 18 | CQ7: 19 | CR7: 20 | CS7: 21 = (18x20) | CT7: 10 | CU7: 11 | CV7: 12 | CW7: 13 = (10x12) | CX7: 14 | CY7: 15 | CZ7: 16 | DA7: 17 = (14x16) | DB7: 18 | DC7: 19 | DD7: 20 | DE7: 21 = (18x20) | DF7: 10 | DG7: 11 | DH7: 12 | DI7: 13 = (10x12) | DJ7: 14 | DK7: 15 | DL7: 16 | DM7: 17 = (14x16) | DN7: 18 | DO7: 19 | DP7: 20 | DQ7: 21 = (18x20) | DR7: 10 | DS7: 11 | DT7: 12 | DU7: 13 = (10x12) | DV7: 14 | DW7: 15 | DX7: 16 | DY7: 17 = (14x16) | DZ7: 18 | EA7: 19 | EB7: 20 | EC7: 21 = (18x20) | ED7: 10 | EE7: 11 | EF7: 12 | EG7: 13 = (10x12) | EH7: 14 | EI7: 15 | EJ7: 16 | EK7: 17 = (14x16) | EL7: 18 | EM7: 19 | EN7: 20 | EO7: 21 = (18x20) | EP7: 10 | EQ7: 11 | ER7: 12 | ES7: 13 = (10x12) | ET7: 14 | EU7: 15 | EV7: 16 | EW7: 17 = (14x16) | EX7: 18 | EY7: 19 | EZ7: 20 | FA7: 21 = (18x20) | FB7: 10 | FC7: 11 | FD7: 12 | FE7: 13 = (10x12) | FF7: 14 | FG7: 15 | FH7: 16 | FI7: 17 = (14x16) | FJ7: 18 | FK7: 19 | FL7: 20 | FM7: 21 = (18x20) | FN7: 10 | FO7: 11 | FP7: 12 | FQ7: 13 = (10x12) | FR7: 14 | FS7: 15 | FT7: 16 | FU7: 17 = (14x16) | FV7: 18 | FW7: 19 | FX7: 20 | FY7: 21 = (18x20) | FZ7: 10 | GA7: 11 | GB7: 12 | GC7: 13 = (10x12) | GD7: 14 | GE7: 15 | GF7: 16 | GG7: 17 = (14x16) | GH7: 18 | GI7: 19 | GJ7: 20 | GK7: 21 = (18x20) | GM7: 10 | GN7: 11 | GO7: 12 | GP7: 13 = (10x12) | GQ7: 14 | GR7: 15 | GS7: 16 | GT7: 17 = (14x16) | GU7: 18 | GV7: 19 | GW7: 20 | GX7: 21 = (18x20) | GZ7: 10 | HA7: 11 | HB7: 12 | HC7: 13 = (10x12) | HD7: 14 | HE7: 15 | HF7: 16 | HG7: 17 = (14x16) | HH7: 18 | HI7: 19 | HJ7: 20 | HK7: 21 = (18x20) | IY7: 10 | IZ7: 11 | JA7: 12 | JB7: 13 = (10x12) | JC7: 14 | JD7: 15 | JE7: 16 | JF7: 17 = (14x16) | JG7: 18 | JH7: 19 | JI7: 20 | JJ7: 21 = (18x20)
A8: 1 | B8: SEKRE/BIDANG/CADISDIK | C8: 5.1.02.01.01.0001 | D8: Bahan-Bahan Bangunan dan Konstruksi
D9: 1 | M9: =J9*L9 -> 0 | Q9: =N9*P9 -> 0 | S9: =O9 -> 0 | T9: =P9 -> 0 | U9: =R9*T9 -> 0 | V9: =J9+N9-R9 -> 0 | W9: =O9 -> 0 | X9: =P9 -> 0 | Y9: =V9*X9 -> 0 | AC9: =Z9*AB9 -> 0 | AE9: =AA9 -> 0 | AF9: =AB9 -> 0 | AG9: =AD9*AF9 -> 0 | AH9: =V9+Z9-AD9 -> 0 | AI9: =AA9 -> 0 | AJ9: =AB9 -> 0 | AK9: =AH9*AJ9 -> 0 | AO9: =AL9*AN9 -> 0 | AQ9: =AM9 -> 0 | AR9: =AN9 -> 0 | AS9: =AP9*AR9 -> 0 | AT9: =AH9+AL9-AP9 -> 0 | AU9: =AM9 -> 0 | AV9: =AN9 -> 0 | AW9: =AT9*AV9 -> 0 | BA9: =AX9*AZ9 -> 0 | BC9: =AY9 -> 0 | BD9: =AZ9 -> 0 | BE9: =BB9*BD9 -> 0 | BF9: =AT9+AX9-BB9 -> 0 | BG9: =AY9 -> 0 | BH9: =AZ9 -> 0 | BI9: =BF9*BH9 -> 0 | BM9: =BJ9*BL9 -> 0 | BO9: =BK9 -> 0 | BP9: =BL9 -> 0 | BQ9: =BN9*BP9 -> 0 | BR9: =BF9+BJ9-BN9 -> 0 | BS9: =BK9 -> 0 | BT9: =BL9 -> 0 | BU9: =BR9*BT9 -> 0 | BY9: =BV9*BX9 -> 0 | CA9: =BW9 -> 0 | CB9: =BX9 -> 0 | CC9: =BZ9*CB9 -> 0 | CD9: =BR9+BV9-BZ9 -> 0 | CE9: =BW9 -> 0 | CF9: =BX9 -> 0 | CG9: =CD9*CF9 -> 0 | CI9: =CE9 -> 0 | CJ9: =CF9 -> 0 | CK9: =CH9*CJ9 -> 0 | CM9: =CI9 -> 0 | CN9: =CJ9 -> 0 | CO9: =CL9*CN9 -> 0 | CP9: =CD9+CH9-CL9 -> 0 | CQ9: =CI9 -> 0 | CR9: =CJ9 -> 0 | CS9: =CP9*CR9 -> 0 | CU9: =CQ9 -> 0 | CV9: =CR9 -> 0 | CW9: =CT9*CV9 -> 0 | CY9: =CU9 -> 0 | CZ9: =CV9 -> 0 | DA9: =CX9*CZ9 -> 0 | DB9: =CP9+CT9-CX9 -> 0 | DC9: =CU9 -> 0 | DD9: =CV9 -> 0 | DE9: =DB9*DD9 -> 0 | DG9: =DC9 -> 0 | DH9: =DD9 -> 0 | DI9: =DF9*DH9 -> 0 | DK9: =DG9 -> 0 | DL9: =DH9 -> 0 | DM9: =DJ9*DL9 -> 0 | DN9: =DB9+DF9-DJ9 -> 0 | DO9: =DG9 -> 0 | DP9: =DH9 -> 0 | DQ9: =DN9*DP9 -> 0 | DS9: =DO9 -> 0 | DT9: =DP9 -> 0 | DU9: =DR9*DT9 -> 0 | DW9: =DS9 -> 0 | DX9: =DT9 -> 0 | DY9: =DV9*DX9 -> 0 | DZ9: =DN9+DR9-DV9 -> 0 | EA9: =DS9 -> 0 | EB9: =DT9 -> 0 | EC9: =DZ9*EB9 -> 0 | EE9: =EA9 -> 0 | EF9: =EB9 -> 0 | EG9: =ED9*EF9 -> 0 | EI9: =EE9 -> 0 | EJ9: =EF9 -> 0 | EK9: =EH9*EJ9 -> 0 | EL9: =DZ9+ED9-EH9 -> 0 | EM9: =EE9 -> 0 | EN9: =EF9 -> 0 | EO9: =EL9*EN9 -> 0 | EQ9: =EM9 -> 0 | ER9: =EN9 -> 0 | ES9: =EP9*ER9 -> 0 | EU9: =EQ9 -> 0 | EV9: =ER9 -> 0 | EW9: =ET9*EV9 -> 0 | EX9: =EL9+EP9-ET9 -> 0 | EY9: =EQ9 -> 0 | EZ9: =ER9 -> 0 | FA9: =EX9*EZ9 -> 0 | FB9: =N9+Z9+AL9 -> 0 | FC9: =AU9 -> 0 | FD9: =AV9 -> 0 | FE9: =FB9*FD9 -> 0 | FF9: =R9+AD9+AP9 -> 0 | FG9: =FC9 -> 0 | FH9: =FD9 -> 0 | FI9: =FF9*FH9 -> 0 | FJ9: =J9+FB9-FF9 -> 0 | FK9: =FG9 -> 0 | FL9: =FH9 -> 0 | FM9: =FJ9*FL9 -> 0 | FN9: =AX9+BJ9+BV9 -> 0 | FO9: =FK9 -> 0 | FP9: =FL9 -> 0 | FQ9: =FN9*FP9 -> 0 | FR9: =BB9+BN9+BZ9 -> 0 | FS9: =FO9 -> 0 | FT9: =FP9 -> 0 | FU9: =FR9*FT9 -> 0 | FV9: =FJ9+FN9-FR9 -> 0 | FW9: =FS9 -> 0 | FX9: =FT9 -> 0 | FY9: =FV9*FX9 -> 0 | FZ9: =FB9+FN9 -> 0 | GA9: =FW9 -> 0 | GB9: =FX9 -> 0 | GC9: =FZ9*GB9 -> 0 | GD9: =FF9+FR9 -> 0 | GE9: =GA9 -> 0 | GF9: =GB9 -> 0 | GG9: =GD9*GF9 -> 0 | GH9: =J9+FZ9-GD9 -> 0 | GI9: =GE9 -> 0 | GJ9: =GF9 -> 0 | GK9: =GH9*GJ9 -> 0 | GM9: =CH9+CT9+DF9 -> 0 | GN9: =DO9 -> 0 | GO9: =DP9 -> 0 | GP9: =GM9*GO9 -> 0 | GQ9: =CL9+CX9+DJ9 -> 0 | GR9: =GN9 -> 0 | GS9: =GO9 -> 0 | GT9: =GQ9*GS9 -> 0 | GU9: =GH9+GM9-GQ9 -> 0 | GV9: =GR9 -> 0 | GW9: =GS9 -> 0 | GX9: =GU9*GW9 -> 0 | GZ9: =FZ9+GM9 -> 0 | HA9: =GV9 -> 0 | HB9: =GW9 -> 0 | HC9: =GZ9*HB9 -> 0 | HD9: =GD9+GQ9 -> 0 | HE9: =HA9 -> 0 | HF9: =HB9 -> 0 | HG9: =HD9*HF9 -> 0 | HH9: =J9+GZ9-HD9 -> 0 | HI9: =HE9 -> 0 | HJ9: =HF9 -> 0 | HK9: =HH9*HJ9 -> 0 | HM9: =ROUNDUP(GZ9,0) -> 0 | HN9: =GZ9-HM9 -> 0 | HO9: =ROUNDUP(HB9,0) -> 0 | HP9: =HB9-HO9 -> 0 | HQ9: =ROUNDUP(HC9,0) -> 0 | HR9: =HC9-HQ9 -> 0 | HS9: =ROUNDUP(HD9,0) -> 0 | HT9: =HD9-HS9 -> 0 | HU9: =ROUNDUP(HF9,0) -> 0 | HV9: =HF9-HU9 -> 0 | HW9: =ROUNDUP(HG9,0) -> 0 | HX9: =HG9-HW9 -> 0 | HY9: =ROUNDUP(HH9,0) -> 0 | HZ9: =HH9-HY9 -> 0 | IA9: =ROUNDUP(HJ9,0) -> 0 | IB9: =HJ9-IA9 -> 0 | IC9: =ROUNDUP(HK9,0) -> 0 | ID9: =HK9-IC9 -> 0 | IF9: =ROUNDUP(DR9,0) -> 0 | IG9: =DR9-IF9 -> 0 | IH9: =ROUNDUP(DT9,0) -> 0 | II9: =DT9-IH9 -> 0 | IJ9: =ROUNDUP(DU9,0) -> 0 | IK9: =DU9-IJ9 -> 0 | IL9: =ROUNDUP(DV9,0) -> 0 | IM9: =DV9-IL9 -> 0 | IN9: =ROUNDUP(DX9,0) -> 0 | IO9: =DX9-IN9 -> 0 | IP9: =ROUNDUP(DY9,0) -> 0 | IQ9: =DY9-IP9 -> 0 | IR9: =ROUNDUP(DZ9,0) -> 0 | IS9: =DZ9-IR9 -> 0 | IT9: =ROUNDUP(EB9,0) -> 0 | IU9: =EB9-IT9 -> 0 | IV9: =ROUNDUP(EC9,0) -> 0 | IW9: =EC9-IV9 -> 0
D10: 2 | M10: =J10*L10 -> 0 | Q10: =N10*P10 -> 0 | S10: =O10 -> 0 | T10: =P10 -> 0 | U10: =R10*T10 -> 0 | V10: =J10+N10-R10 -> 0 | W10: =O10 -> 0 | X10: =P10 -> 0 | Y10: =V10*X10 -> 0 | AC10: =Z10*AB10 -> 0 | AE10: =AA10 -> 0 | AF10: =AB10 -> 0 | AG10: =AD10*AF10 -> 0 | AH10: =V10+Z10-AD10 -> 0 | AI10: =AA10 -> 0 | AJ10: =AB10 -> 0 | AK10: =AH10*AJ10 -> 0 | AO10: =AL10*AN10 -> 0 | AQ10: =AM10 -> 0 | AR10: =AN10 -> 0 | AS10: =AP10*AR10 -> 0 | AT10: =AH10+AL10-AP10 -> 0 | AU10: =AM10 -> 0 | AV10: =AN10 -> 0 | AW10: =AT10*AV10 -> 0 | BA10: =AX10*AZ10 -> 0 | BC10: =AY10 -> 0 | BD10: =AZ10 -> 0 | BE10: =BB10*BD10 -> 0 | BF10: =AT10+AX10-BB10 -> 0 | BG10: =AY10 -> 0 | BH10: =AZ10 -> 0 | BI10: =BF10*BH10 -> 0 | BM10: =BJ10*BL10 -> 0 | BO10: =BK10 -> 0 | BP10: =BL10 -> 0 | BQ10: =BN10*BP10 -> 0 | BR10: =BF10+BJ10-BN10 -> 0 | BS10: =BK10 -> 0 | BT10: =BL10 -> 0 | BU10: =BR10*BT10 -> 0 | BY10: =BV10*BX10 -> 0 | CA10: =BW10 -> 0 | CB10: =BX10 -> 0 | CC10: =BZ10*CB10 -> 0 | CD10: =BR10+BV10-BZ10 -> 0 | CE10: =BW10 -> 0 | CF10: =BX10 -> 0 | CG10: =CD10*CF10 -> 0 | CI10: =CE10 -> 0 | CJ10: =CF10 -> 0 | CK10: =CH10*CJ10 -> 0 | CM10: =CI10 -> 0 | CN10: =CJ10 -> 0 | CO10: =CL10*CN10 -> 0 | CP10: =CD10+CH10-CL10 -> 0 | CQ10: =CI10 -> 0 | CR10: =CJ10 -> 0 | CS10: =CP10*CR10 -> 0 | CU10: =CQ10 -> 0 | CV10: =CR10 -> 0 | CW10: =CT10*CV10 -> 0 | CY10: =CU10 -> 0 | CZ10: =CV10 -> 0 | DA10: =CX10*CZ10 -> 0 | DB10: =CP10+CT10-CX10 -> 0 | DC10: =CU10 -> 0 | DD10: =CV10 -> 0 | DE10: =DB10*DD10 -> 0 | DG10: =DC10 -> 0 | DH10: =DD10 -> 0 | DI10: =DF10*DH10 -> 0 | DK10: =DG10 -> 0 | DL10: =DH10 -> 0 | DM10: =DJ10*DL10 -> 0 | DN10: =DB10+DF10-DJ10 -> 0 | DO10: =DG10 -> 0 | DP10: =DH10 -> 0 | DQ10: =DN10*DP10 -> 0 | DS10: =DO10 -> 0 | DT10: =DP10 -> 0 | DU10: =DR10*DT10 -> 0 | DW10: =DS10 -> 0 | DX10: =DT10 -> 0 | DY10: =DV10*DX10 -> 0 | DZ10: =DN10+DR10-DV10 -> 0 | EA10: =DS10 -> 0 | EB10: =DT10 -> 0 | EC10: =DZ10*EB10 -> 0 | EE10: =EA10 -> 0 | EF10: =EB10 -> 0 | EG10: =ED10*EF10 -> 0 | EI10: =EE10 -> 0 | EJ10: =EF10 -> 0 | EK10: =EH10*EJ10 -> 0 | EL10: =DZ10+ED10-EH10 -> 0 | EM10: =EE10 -> 0 | EN10: =EF10 -> 0 | EO10: =EL10*EN10 -> 0 | EQ10: =EM10 -> 0 | ER10: =EN10 -> 0 | ES10: =EP10*ER10 -> 0 | EU10: =EQ10 -> 0 | EV10: =ER10 -> 0 | EW10: =ET10*EV10 -> 0 | EX10: =EL10+EP10-ET10 -> 0 | EY10: =EQ10 -> 0 | EZ10: =ER10 -> 0 | FA10: =EX10*EZ10 -> 0 | FB10: =N10+Z10+AL10 -> 0 | FC10: =AU10 -> 0 | FD10: =AV10 -> 0 | FE10: =FB10*FD10 -> 0 | FF10: =R10+AD10+AP10 -> 0 | FG10: =FC10 -> 0 | FH10: =FD10 -> 0 | FI10: =FF10*FH10 -> 0 | FJ10: =J10+FB10-FF10 -> 0 | FK10: =FG10 -> 0 | FL10: =FH10 -> 0 | FM10: =FJ10*FL10 -> 0 | FN10: =AX10+BJ10+BV10 -> 0 | FO10: =FK10 -> 0 | FP10: =FL10 -> 0 | FQ10: =FN10*FP10 -> 0 | FR10: =BB10+BN10+BZ10 -> 0 | FS10: =FO10 -> 0 | FT10: =FP10 -> 0 | FU10: =FR10*FT10 -> 0 | FV10: =FJ10+FN10-FR10 -> 0 | FW10: =FS10 -> 0 | FX10: =FT10 -> 0 | FY10: =FV10*FX10 -> 0 | FZ10: =FB10+FN10 -> 0 | GA10: =FW10 -> 0 | GB10: =FX10 -> 0 | GC10: =FZ10*GB10 -> 0 | GD10: =FF10+FR10 -> 0 | GE10: =GA10 -> 0 | GF10: =GB10 -> 0 | GG10: =GD10*GF10 -> 0 | GH10: =J10+FZ10-GD10 -> 0 | GI10: =GE10 -> 0 | GJ10: =GF10 -> 0 | GK10: =GH10*GJ10 -> 0 | GM10: =CH10+CT10+DF10 -> 0 | GN10: =DO10 -> 0 | GO10: =DP10 -> 0 | GP10: =GM10*GO10 -> 0 | GQ10: =CL10+CX10+DJ10 -> 0 | GR10: =GN10 -> 0 | GS10: =GO10 -> 0 | GT10: =GQ10*GS10 -> 0 | GU10: =GH10+GM10-GQ10 -> 0 | GV10: =GR10 -> 0 | GW10: =GS10 -> 0 | GX10: =GU10*GW10 -> 0 | GZ10: =FZ10+GM10 -> 0 | HA10: =GV10 -> 0 | HB10: =GW10 -> 0 | HC10: =GZ10*HB10 -> 0 | HD10: =GD10+GQ10 -> 0 | HE10: =HA10 -> 0 | HF10: =HB10 -> 0 | HG10: =HD10*HF10 -> 0 | HH10: =J10+GZ10-HD10 -> 0 | HI10: =HE10 -> 0 | HJ10: =HF10 -> 0 | HK10: =HH10*HJ10 -> 0 | HM10: =ROUNDUP(GZ10,0) -> 0 | HN10: =GZ10-HM10 -> 0 | HO10: =ROUNDUP(HB10,0) -> 0 | HP10: =HB10-HO10 -> 0 | HQ10: =ROUNDUP(HC10,0) -> 0 | HR10: =HC10-HQ10 -> 0 | HS10: =ROUNDUP(HD10,0) -> 0 | HT10: =HD10-HS10 -> 0 | HU10: =ROUNDUP(HF10,0) -> 0 | HV10: =HF10-HU10 -> 0 | HW10: =ROUNDUP(HG10,0) -> 0 | HX10: =HG10-HW10 -> 0 | HY10: =ROUNDUP(HH10,0) -> 0 | HZ10: =HH10-HY10 -> 0 | IA10: =ROUNDUP(HJ10,0) -> 0 | IB10: =HJ10-IA10 -> 0 | IC10: =ROUNDUP(HK10,0) -> 0 | ID10: =HK10-IC10 -> 0 | IF10: =ROUNDUP(DR10,0) -> 0 | IG10: =DR10-IF10 -> 0 | IH10: =ROUNDUP(DT10,0) -> 0 | II10: =DT10-IH10 -> 0 | IJ10: =ROUNDUP(DU10,0) -> 0 | IK10: =DU10-IJ10 -> 0 | IL10: =ROUNDUP(DV10,0) -> 0 | IM10: =DV10-IL10 -> 0 | IN10: =ROUNDUP(DX10,0) -> 0 | IO10: =DX10-IN10 -> 0 | IP10: =ROUNDUP(DY10,0) -> 0 | IQ10: =DY10-IP10 -> 0 | IR10: =ROUNDUP(DZ10,0) -> 0 | IS10: =DZ10-IR10 -> 0 | IT10: =ROUNDUP(EB10,0) -> 0 | IU10: =EB10-IT10 -> 0 | IV10: =ROUNDUP(EC10,0) -> 0 | IW10: =EC10-IV10 -> 0
D11: dst.. | M11: =J11*L11 -> 0 | Q11: =N11*P11 -> 0 | S11: =O11 -> 0 | T11: =P11 -> 0 | U11: =R11*T11 -> 0 | V11: =J11+N11-R11 -> 0 | W11: =O11 -> 0 | X11: =P11 -> 0 | Y11: =V11*X11 -> 0 | AC11: =Z11*AB11 -> 0 | AE11: =AA11 -> 0 | AF11: =AB11 -> 0 | AG11: =AD11*AF11 -> 0 | AH11: =V11+Z11-AD11 -> 0 | AI11: =AA11 -> 0 | AJ11: =AB11 -> 0 | AK11: =AH11*AJ11 -> 0 | AO11: =AL11*AN11 -> 0 | AQ11: =AM11 -> 0 | AR11: =AN11 -> 0 | AS11: =AP11*AR11 -> 0 | AT11: =AH11+AL11-AP11 -> 0 | AU11: =AM11 -> 0 | AV11: =AN11 -> 0 | AW11: =AT11*AV11 -> 0 | BA11: =AX11*AZ11 -> 0 | BC11: =AY11 -> 0 | BD11: =AZ11 -> 0 | BE11: =BB11*BD11 -> 0 | BF11: =AT11+AX11-BB11 -> 0 | BG11: =AY11 -> 0 | BH11: =AZ11 -> 0 | BI11: =BF11*BH11 -> 0 | BM11: =BJ11*BL11 -> 0 | BO11: =BK11 -> 0 | BP11: =BL11 -> 0 | BQ11: =BN11*BP11 -> 0 | BR11: =BF11+BJ11-BN11 -> 0 | BS11: =BK11 -> 0 | BT11: =BL11 -> 0 | BU11: =BR11*BT11 -> 0 | BY11: =BV11*BX11 -> 0 | CA11: =BW11 -> 0 | CB11: =BX11 -> 0 | CC11: =BZ11*CB11 -> 0 | CD11: =BR11+BV11-BZ11 -> 0 | CE11: =BW11 -> 0 | CF11: =BX11 -> 0 | CG11: =CD11*CF11 -> 0 | CI11: =CE11 -> 0 | CJ11: =CF11 -> 0 | CK11: =CH11*CJ11 -> 0 | CM11: =CI11 -> 0 | CN11: =CJ11 -> 0 | CO11: =CL11*CN11 -> 0 | CP11: =CD11+CH11-CL11 -> 0 | CQ11: =CI11 -> 0 | CR11: =CJ11 -> 0 | CS11: =CP11*CR11 -> 0 | CU11: =CQ11 -> 0 | CV11: =CR11 -> 0 | CW11: =CT11*CV11 -> 0 | CY11: =CU11 -> 0 | CZ11: =CV11 -> 0 | DA11: =CX11*CZ11 -> 0 | DB11: =CP11+CT11-CX11 -> 0 | DC11: =CU11 -> 0 | DD11: =CV11 -> 0 | DE11: =DB11*DD11 -> 0 | DG11: =DC11 -> 0 | DH11: =DD11 -> 0 | DI11: =DF11*DH11 -> 0 | DK11: =DG11 -> 0 | DL11: =DH11 -> 0 | DM11: =DJ11*DL11 -> 0 | DN11: =DB11+DF11-DJ11 -> 0 | DO11: =DG11 -> 0 | DP11: =DH11 -> 0 | DQ11: =DN11*DP11 -> 0 | DS11: =DO11 -> 0 | DT11: =DP11 -> 0 | DU11: =DR11*DT11 -> 0 | DW11: =DS11 -> 0 | DX11: =DT11 -> 0 | DY11: =DV11*DX11 -> 0 | DZ11: =DN11+DR11-DV11 -> 0 | EA11: =DS11 -> 0 | EB11: =DT11 -> 0 | EC11: =DZ11*EB11 -> 0 | EE11: =EA11 -> 0 | EF11: =EB11 -> 0 | EG11: =ED11*EF11 -> 0 | EI11: =EE11 -> 0 | EJ11: =EF11 -> 0 | EK11: =EH11*EJ11 -> 0 | EL11: =DZ11+ED11-EH11 -> 0 | EM11: =EE11 -> 0 | EN11: =EF11 -> 0 | EO11: =EL11*EN11 -> 0 | EQ11: =EM11 -> 0 | ER11: =EN11 -> 0 | ES11: =EP11*ER11 -> 0 | EU11: =EQ11 -> 0 | EV11: =ER11 -> 0 | EW11: =ET11*EV11 -> 0 | EX11: =EL11+EP11-ET11 -> 0 | EY11: =EQ11 -> 0 | EZ11: =ER11 -> 0 | FA11: =EX11*EZ11 -> 0 | FB11: =N11+Z11+AL11 -> 0 | FC11: =AU11 -> 0 | FD11: =AV11 -> 0 | FE11: =FB11*FD11 -> 0 | FF11: =R11+AD11+AP11 -> 0 | FG11: =FC11 -> 0 | FH11: =FD11 -> 0 | FI11: =FF11*FH11 -> 0 | FJ11: =J11+FB11-FF11 -> 0 | FK11: =FG11 -> 0 | FL11: =FH11 -> 0 | FM11: =FJ11*FL11 -> 0 | FN11: =AX11+BJ11+BV11 -> 0 | FO11: =FK11 -> 0 | FP11: =FL11 -> 0 | FQ11: =FN11*FP11 -> 0 | FR11: =BB11+BN11+BZ11 -> 0 | FS11: =FO11 -> 0 | FT11: =FP11 -> 0 | FU11: =FR11*FT11 -> 0 | FV11: =FJ11+FN11-FR11 -> 0 | FW11: =FS11 -> 0 | FX11: =FT11 -> 0 | FY11: =FV11*FX11 -> 0 | FZ11: =FB11+FN11 -> 0 | GA11: =FW11 -> 0 | GB11: =FX11 -> 0 | GC11: =FZ11*GB11 -> 0 | GD11: =FF11+FR11 -> 0 | GE11: =GA11 -> 0 | GF11: =GB11 -> 0 | GG11: =GD11*GF11 -> 0 | GH11: =J11+FZ11-GD11 -> 0 | GI11: =GE11 -> 0 | GJ11: =GF11 -> 0 | GK11: =GH11*GJ11 -> 0 | GM11: =CH11+CT11+DF11 -> 0 | GN11: =DO11 -> 0 | GO11: =DP11 -> 0 | GP11: =GM11*GO11 -> 0 | GQ11: =CL11+CX11+DJ11 -> 0 | GR11: =GN11 -> 0 | GS11: =GO11 -> 0 | GT11: =GQ11*GS11 -> 0 | GU11: =GH11+GM11-GQ11 -> 0 | GV11: =GR11 -> 0 | GW11: =GS11 -> 0 | GX11: =GU11*GW11 -> 0 | GZ11: =FZ11+GM11 -> 0 | HA11: =GV11 -> 0 | HB11: =GW11 -> 0 | HC11: =GZ11*HB11 -> 0 | HD11: =GD11+GQ11 -> 0 | HE11: =HA11 -> 0 | HF11: =HB11 -> 0 | HG11: =HD11*HF11 -> 0 | HH11: =J11+GZ11-HD11 -> 0 | HI11: =HE11 -> 0 | HJ11: =HF11 -> 0 | HK11: =HH11*HJ11 -> 0 | HM11: =ROUNDUP(GZ11,0) -> 0 | HN11: =GZ11-HM11 -> 0 | HO11: =ROUNDUP(HB11,0) -> 0 | HP11: =HB11-HO11 -> 0 | HQ11: =ROUNDUP(HC11,0) -> 0 | HR11: =HC11-HQ11 -> 0 | HS11: =ROUNDUP(HD11,0) -> 0 | HT11: =HD11-HS11 -> 0 | HU11: =ROUNDUP(HF11,0) -> 0 | HV11: =HF11-HU11 -> 0 | HW11: =ROUNDUP(HG11,0) -> 0 | HX11: =HG11-HW11 -> 0 | HY11: =ROUNDUP(HH11,0) -> 0 | HZ11: =HH11-HY11 -> 0 | IA11: =ROUNDUP(HJ11,0) -> 0 | IB11: =HJ11-IA11 -> 0 | IC11: =ROUNDUP(HK11,0) -> 0 | ID11: =HK11-IC11 -> 0 | IF11: =ROUNDUP(DR11,0) -> 0 | IG11: =DR11-IF11 -> 0 | IH11: =ROUNDUP(DT11,0) -> 0 | II11: =DT11-IH11 -> 0 | IJ11: =ROUNDUP(DU11,0) -> 0 | IK11: =DU11-IJ11 -> 0 | IL11: =ROUNDUP(DV11,0) -> 0 | IM11: =DV11-IL11 -> 0 | IN11: =ROUNDUP(DX11,0) -> 0 | IO11: =DX11-IN11 -> 0 | IP11: =ROUNDUP(DY11,0) -> 0 | IQ11: =DY11-IP11 -> 0 | IR11: =ROUNDUP(DZ11,0) -> 0 | IS11: =DZ11-IR11 -> 0 | IT11: =ROUNDUP(EB11,0) -> 0 | IU11: =EB11-IT11 -> 0 | IV11: =ROUNDUP(EC11,0) -> 0 | IW11: =EC11-IV11 -> 0
D12: TOTAL | M12: =SUM(M9:M11) -> 0 | Q12: =SUM(Q9:Q11) -> 0 | U12: =SUM(U9:U11) -> 0 | Y12: =SUM(Y9:Y11) -> 0 | AC12: =SUM(AC9:AC11) -> 0 | AG12: =SUM(AG9:AG11) -> 0 | AK12: =SUM(AK9:AK11) -> 0 | AO12: =SUM(AO9:AO11) -> 0 | AS12: =SUM(AS9:AS11) -> 0 | AW12: =SUM(AW9:AW11) -> 0 | BA12: =SUM(BA9:BA11) -> 0 | BE12: =SUM(BE9:BE11) -> 0 | BI12: =SUM(BI9:BI11) -> 0 | BM12: =SUM(BM9:BM11) -> 0 | BQ12: =SUM(BQ9:BQ11) -> 0 | BU12: =SUM(BU9:BU11) -> 0 | BY12: =SUM(BY9:BY11) -> 0 | CC12: =SUM(CC9:CC11) -> 0 | CG12: =SUM(CG9:CG11) -> 0 | CK12: =SUM(CK9:CK11) -> 0 | CO12: =SUM(CO9:CO11) -> 0 | CS12: =SUM(CS9:CS11) -> 0 | CW12: =SUM(CW9:CW11) -> 0 | DA12: =SUM(DA9:DA11) -> 0 | DE12: =SUM(DE9:DE11) -> 0 | DI12: =SUM(DI9:DI11) -> 0 | DM12: =SUM(DM9:DM11) -> 0 | DQ12: =SUM(DQ9:DQ11) -> 0 | DU12: =SUM(DU9:DU11) -> 0 | DY12: =SUM(DY9:DY11) -> 0 | EC12: =SUM(EC9:EC11) -> 0 | EG12: =SUM(EG9:EG11) -> 0 | EK12: =SUM(EK9:EK11) -> 0 | EO12: =SUM(EO9:EO11) -> 0 | ES12: =SUM(ES9:ES11) -> 0 | EW12: =SUM(EW9:EW11) -> 0 | FA12: =SUM(FA9:FA11) -> 0
A13: 2 | C13: 5.1.02.01.01.0004 | D13: Bahan-Bahan Bakar dan Pelumas
D14: 1 | M14: =J14*L14 -> 0 | Q14: =N14*P14 -> 0 | S14: =O14 -> 0 | T14: =P14 -> 0 | U14: =R14*T14 -> 0 | V14: =J14+N14-R14 -> 0 | W14: =O14 -> 0 | X14: =P14 -> 0 | Y14: =V14*X14 -> 0 | AC14: =Z14*AB14 -> 0 | AE14: =AA14 -> 0 | AF14: =AB14 -> 0 | AG14: =AD14*AF14 -> 0 | AH14: =V14+Z14-AD14 -> 0 | AI14: =AA14 -> 0 | AJ14: =AB14 -> 0 | AK14: =AH14*AJ14 -> 0 | AO14: =AL14*AN14 -> 0 | AQ14: =AM14 -> 0 | AR14: =AN14 -> 0 | AS14: =AP14*AR14 -> 0 | AT14: =AH14+AL14-AP14 -> 0 | AU14: =AM14 -> 0 | AV14: =AN14 -> 0 | AW14: =AT14*AV14 -> 0 | BA14: =AX14*AZ14 -> 0 | BC14: =AY14 -> 0 | BD14: =AZ14 -> 0 | BE14: =BB14*BD14 -> 0 | BF14: =AT14+AX14-BB14 -> 0 | BG14: =AY14 -> 0 | BH14: =AZ14 -> 0 | BI14: =BF14*BH14 -> 0 | BM14: =BJ14*BL14 -> 0 | BO14: =BK14 -> 0 | BP14: =BL14 -> 0 | BQ14: =BN14*BP14 -> 0 | BR14: =BF14+BJ14-BN14 -> 0 | BS14: =BK14 -> 0 | BT14: =BL14 -> 0 | BU14: =BR14*BT14 -> 0 | BY14: =BV14*BX14 -> 0 | CA14: =BW14 -> 0 | CB14: =BX14 -> 0 | CC14: =BZ14*CB14 -> 0 | CD14: =BR14+BV14-BZ14 -> 0 | CE14: =BW14 -> 0 | CF14: =BX14 -> 0 | CG14: =CD14*CF14 -> 0 | CI14: =CE14 -> 0 | CJ14: =CF14 -> 0 | CK14: =CH14*CJ14 -> 0 | CM14: =CI14 -> 0 | CN14: =CJ14 -> 0 | CO14: =CL14*CN14 -> 0 | CP14: =CD14+CH14-CL14 -> 0 | CQ14: =CI14 -> 0 | CR14: =CJ14 -> 0 | CS14: =CP14*CR14 -> 0 | CU14: =CQ14 -> 0 | CV14: =CR14 -> 0 | CW14: =CT14*CV14 -> 0 | CY14: =CU14 -> 0 | CZ14: =CV14 -> 0 | DA14: =CX14*CZ14 -> 0 | DB14: =CP14+CT14-CX14 -> 0 | DC14: =CU14 -> 0 | DD14: =CV14 -> 0 | DE14: =DB14*DD14 -> 0 | DG14: =DC14 -> 0 | DH14: =DD14 -> 0 | DI14: =DF14*DH14 -> 0 | DK14: =DG14 -> 0 | DL14: =DH14 -> 0 | DM14: =DJ14*DL14 -> 0 | DN14: =DB14+DF14-DJ14 -> 0 | DO14: =DG14 -> 0 | DP14: =DH14 -> 0 | DQ14: =DN14*DP14 -> 0 | DS14: =DO14 -> 0 | DT14: =DP14 -> 0 | DU14: =DR14*DT14 -> 0 | DW14: =DS14 -> 0 | DX14: =DT14 -> 0 | DY14: =DV14*DX14 -> 0 | DZ14: =DN14+DR14-DV14 -> 0 | EA14: =DS14 -> 0 | EB14: =DT14 -> 0 | EC14: =DZ14*EB14 -> 0 | EE14: =EA14 -> 0 | EF14: =EB14 -> 0 | EG14: =ED14*EF14 -> 0 | EI14: =EE14 -> 0 | EJ14: =EF14 -> 0 | EK14: =EH14*EJ14 -> 0 | EL14: =DZ14+ED14-EH14 -> 0 | EM14: =EE14 -> 0 | EN14: =EF14 -> 0 | EO14: =EL14*EN14 -> 0 | EQ14: =EM14 -> 0 | ER14: =EN14 -> 0 | ES14: =EP14*ER14 -> 0 | EU14: =EQ14 -> 0 | EV14: =ER14 -> 0 | EW14: =ET14*EV14 -> 0 | EX14: =EL14+EP14-ET14 -> 0 | EY14: =EQ14 -> 0 | EZ14: =ER14 -> 0 | FA14: =EX14*EZ14 -> 0 | FB14: =N14+Z14+AL14 -> 0 | FC14: =AU14 -> 0 | FD14: =AV14 -> 0 | FE14: =FB14*FD14 -> 0 | FF14: =R14+AD14+AP14 -> 0 | FG14: =FC14 -> 0 | FH14: =FD14 -> 0 | FI14: =FF14*FH14 -> 0 | FJ14: =J14+FB14-FF14 -> 0 | FK14: =FG14 -> 0 | FL14: =FH14 -> 0 | FM14: =FJ14*FL14 -> 0 | FN14: =AX14+BJ14+BV14 -> 0 | FO14: =FK14 -> 0 | FP14: =FL14 -> 0 | FQ14: =FN14*FP14 -> 0 | FR14: =BB14+BN14+BZ14 -> 0 | FS14: =FO14 -> 0 | FT14: =FP14 -> 0 | FU14: =FR14*FT14 -> 0 | FV14: =FJ14+FN14-FR14 -> 0 | FW14: =FS14 -> 0 | FX14: =FT14 -> 0 | FY14: =FV14*FX14 -> 0 | FZ14: =FB14+FN14 -> 0 | GA14: =FW14 -> 0 | GB14: =FX14 -> 0 | GC14: =FZ14*GB14 -> 0 | GD14: =FF14+FR14 -> 0 | GE14: =GA14 -> 0 | GF14: =GB14 -> 0 | GG14: =GD14*GF14 -> 0 | GH14: =J14+FZ14-GD14 -> 0 | GI14: =GE14 -> 0 | GJ14: =GF14 -> 0 | GK14: =GH14*GJ14 -> 0 | GM14: =CH14+CT14+DF14 -> 0 | GN14: =DO14 -> 0 | GO14: =DP14 -> 0 | GP14: =GM14*GO14 -> 0 | GQ14: =CL14+CX14+DJ14 -> 0 | GR14: =GN14 -> 0 | GS14: =GO14 -> 0 | GT14: =GQ14*GS14 -> 0 | GU14: =GH14+GM14-GQ14 -> 0 | GV14: =GR14 -> 0 | GW14: =GS14 -> 0 | GX14: =GU14*GW14 -> 0 | GZ14: =FZ14+GM14 -> 0 | HA14: =GV14 -> 0 | HB14: =GW14 -> 0 | HC14: =GZ14*HB14 -> 0 | HD14: =GD14+GQ14 -> 0 | HE14: =HA14 -> 0 | HF14: =HB14 -> 0 | HG14: =HD14*HF14 -> 0 | HH14: =J14+GZ14-HD14 -> 0 | HI14: =HE14 -> 0 | HJ14: =HF14 -> 0 | HK14: =HH14*HJ14 -> 0 | HM14: =ROUNDUP(GZ14,0) -> 0 | HN14: =GZ14-HM14 -> 0 | HO14: =ROUNDUP(HB14,0) -> 0 | HP14: =HB14-HO14 -> 0 | HQ14: =ROUNDUP(HC14,0) -> 0 | HR14: =HC14-HQ14 -> 0 | HS14: =ROUNDUP(HD14,0) -> 0 | HT14: =HD14-HS14 -> 0 | HU14: =ROUNDUP(HF14,0) -> 0 | HV14: =HF14-HU14 -> 0 | HW14: =ROUNDUP(HG14,0) -> 0 | HX14: =HG14-HW14 -> 0 | HY14: =ROUNDUP(HH14,0) -> 0 | HZ14: =HH14-HY14 -> 0 | IA14: =ROUNDUP(HJ14,0) -> 0 | IB14: =HJ14-IA14 -> 0 | IC14: =ROUNDUP(HK14,0) -> 0 | ID14: =HK14-IC14 -> 0 | IF14: =ROUNDUP(DR14,0) -> 0 | IG14: =DR14-IF14 -> 0 | IH14: =ROUNDUP(DT14,0) -> 0 | II14: =DT14-IH14 -> 0 | IJ14: =ROUNDUP(DU14,0) -> 0 | IK14: =DU14-IJ14 -> 0 | IL14: =ROUNDUP(DV14,0) -> 0 | IM14: =DV14-IL14 -> 0 | IN14: =ROUNDUP(DX14,0) -> 0 | IO14: =DX14-IN14 -> 0 | IP14: =ROUNDUP(DY14,0) -> 0 | IQ14: =DY14-IP14 -> 0 | IR14: =ROUNDUP(DZ14,0) -> 0 | IS14: =DZ14-IR14 -> 0 | IT14: =ROUNDUP(EB14,0) -> 0 | IU14: =EB14-IT14 -> 0 | IV14: =ROUNDUP(EC14,0) -> 0 | IW14: =EC14-IV14 -> 0
D15: 2 | M15: =J15*L15 -> 0 | Q15: =N15*P15 -> 0 | S15: =O15 -> 0 | T15: =P15 -> 0 | U15: =R15*T15 -> 0 | V15: =J15+N15-R15 -> 0 | W15: =O15 -> 0 | X15: =P15 -> 0 | Y15: =V15*X15 -> 0 | AC15: =Z15*AB15 -> 0 | AE15: =AA15 -> 0 | AF15: =AB15 -> 0 | AG15: =AD15*AF15 -> 0 | AH15: =V15+Z15-AD15 -> 0 | AI15: =AA15 -> 0 | AJ15: =AB15 -> 0 | AK15: =AH15*AJ15 -> 0 | AO15: =AL15*AN15 -> 0 | AQ15: =AM15 -> 0 | AR15: =AN15 -> 0 | AS15: =AP15*AR15 -> 0 | AT15: =AH15+AL15-AP15 -> 0 | AU15: =AM15 -> 0 | AV15: =AN15 -> 0 | AW15: =AT15*AV15 -> 0 | BA15: =AX15*AZ15 -> 0 | BC15: =AY15 -> 0 | BD15: =AZ15 -> 0 | BE15: =BB15*BD15 -> 0 | BF15: =AT15+AX15-BB15 -> 0 | BG15: =AY15 -> 0 | BH15: =AZ15 -> 0 | BI15: =BF15*BH15 -> 0 | BM15: =BJ15*BL15 -> 0 | BO15: =BK15 -> 0 | BP15: =BL15 -> 0 | BQ15: =BN15*BP15 -> 0 | BR15: =BF15+BJ15-BN15 -> 0 | BS15: =BK15 -> 0 | BT15: =BL15 -> 0 | BU15: =BR15*BT15 -> 0 | BY15: =BV15*BX15 -> 0 | CA15: =BW15 -> 0 | CB15: =BX15 -> 0 | CC15: =BZ15*CB15 -> 0 | CD15: =BR15+BV15-BZ15 -> 0 | CE15: =BW15 -> 0 | CF15: =BX15 -> 0 | CG15: =CD15*CF15 -> 0 | CI15: =CE15 -> 0 | CJ15: =CF15 -> 0 | CK15: =CH15*CJ15 -> 0 | CM15: =CI15 -> 0 | CN15: =CJ15 -> 0 | CO15: =CL15*CN15 -> 0 | CP15: =CD15+CH15-CL15 -> 0 | CQ15: =CI15 -> 0 | CR15: =CJ15 -> 0 | CS15: =CP15*CR15 -> 0 | CU15: =CQ15 -> 0 | CV15: =CR15 -> 0 | CW15: =CT15*CV15 -> 0 | CY15: =CU15 -> 0 | CZ15: =CV15 -> 0 | DA15: =CX15*CZ15 -> 0 | DB15: =CP15+CT15-CX15 -> 0 | DC15: =CU15 -> 0 | DD15: =CV15 -> 0 | DE15: =DB15*DD15 -> 0 | DG15: =DC15 -> 0 | DH15: =DD15 -> 0 | DI15: =DF15*DH15 -> 0 | DK15: =DG15 -> 0 | DL15: =DH15 -> 0 | DM15: =DJ15*DL15 -> 0 | DN15: =DB15+DF15-DJ15 -> 0 | DO15: =DG15 -> 0 | DP15: =DH15 -> 0 | DQ15: =DN15*DP15 -> 0 | DS15: =DO15 -> 0 | DT15: =DP15 -> 0 | DU15: =DR15*DT15 -> 0 | DW15: =DS15 -> 0 | DX15: =DT15 -> 0 | DY15: =DV15*DX15 -> 0 | DZ15: =DN15+DR15-DV15 -> 0 | EA15: =DS15 -> 0 | EB15: =DT15 -> 0 | EC15: =DZ15*EB15 -> 0 | EE15: =EA15 -> 0 | EF15: =EB15 -> 0 | EG15: =ED15*EF15 -> 0 | EI15: =EE15 -> 0 | EJ15: =EF15 -> 0 | EK15: =EH15*EJ15 -> 0 | EL15: =DZ15+ED15-EH15 -> 0 | EM15: =EE15 -> 0 | EN15: =EF15 -> 0 | EO15: =EL15*EN15 -> 0 | EQ15: =EM15 -> 0 | ER15: =EN15 -> 0 | ES15: =EP15*ER15 -> 0 | EU15: =EQ15 -> 0 | EV15: =ER15 -> 0 | EW15: =ET15*EV15 -> 0 | EX15: =EL15+EP15-ET15 -> 0 | EY15: =EQ15 -> 0 | EZ15: =ER15 -> 0 | FA15: =EX15*EZ15 -> 0 | FB15: =N15+Z15+AL15 -> 0 | FC15: =AU15 -> 0 | FD15: =AV15 -> 0 | FE15: =FB15*FD15 -> 0 | FF15: =R15+AD15+AP15 -> 0 | FG15: =FC15 -> 0 | FH15: =FD15 -> 0 | FI15: =FF15*FH15 -> 0 | FJ15: =J15+FB15-FF15 -> 0 | FK15: =FG15 -> 0 | FL15: =FH15 -> 0 | FM15: =FJ15*FL15 -> 0 | FN15: =AX15+BJ15+BV15 -> 0 | FO15: =FK15 -> 0 | FP15: =FL15 -> 0 | FQ15: =FN15*FP15 -> 0 | FR15: =BB15+BN15+BZ15 -> 0 | FS15: =FO15 -> 0 | FT15: =FP15 -> 0 | FU15: =FR15*FT15 -> 0 | FV15: =FJ15+FN15-FR15 -> 0 | FW15: =FS15 -> 0 | FX15: =FT15 -> 0 | FY15: =FV15*FX15 -> 0 | FZ15: =FB15+FN15 -> 0 | GA15: =FW15 -> 0 | GB15: =FX15 -> 0 | GC15: =FZ15*GB15 -> 0 | GD15: =FF15+FR15 -> 0 | GE15: =GA15 -> 0 | GF15: =GB15 -> 0 | GG15: =GD15*GF15 -> 0 | GH15: =J15+FZ15-GD15 -> 0 | GI15: =GE15 -> 0 | GJ15: =GF15 -> 0 | GK15: =GH15*GJ15 -> 0 | GM15: =CH15+CT15+DF15 -> 0 | GN15: =DO15 -> 0 | GO15: =DP15 -> 0 | GP15: =GM15*GO15 -> 0 | GQ15: =CL15+CX15+DJ15 -> 0 | GR15: =GN15 -> 0 | GS15: =GO15 -> 0 | GT15: =GQ15*GS15 -> 0 | GU15: =GH15+GM15-GQ15 -> 0 | GV15: =GR15 -> 0 | GW15: =GS15 -> 0 | GX15: =GU15*GW15 -> 0 | GZ15: =FZ15+GM15 -> 0 | HA15: =GV15 -> 0 | HB15: =GW15 -> 0 | HC15: =GZ15*HB15 -> 0 | HD15: =GD15+GQ15 -> 0 | HE15: =HA15 -> 0 | HF15: =HB15 -> 0 | HG15: =HD15*HF15 -> 0 | HH15: =J15+GZ15-HD15 -> 0 | HI15: =HE15 -> 0 | HJ15: =HF15 -> 0 | HK15: =HH15*HJ15 -> 0 | HM15: =ROUNDUP(GZ15,0) -> 0 | HN15: =GZ15-HM15 -> 0 | HO15: =ROUNDUP(HB15,0) -> 0 | HP15: =HB15-HO15 -> 0 | HQ15: =ROUNDUP(HC15,0) -> 0 | HR15: =HC15-HQ15 -> 0 | HS15: =ROUNDUP(HD15,0) -> 0 | HT15: =HD15-HS15 -> 0 | HU15: =ROUNDUP(HF15,0) -> 0 | HV15: =HF15-HU15 -> 0 | HW15: =ROUNDUP(HG15,0) -> 0 | HX15: =HG15-HW15 -> 0 | HY15: =ROUNDUP(HH15,0) -> 0 | HZ15: =HH15-HY15 -> 0 | IA15: =ROUNDUP(HJ15,0) -> 0 | IB15: =HJ15-IA15 -> 0 | IC15: =ROUNDUP(HK15,0) -> 0 | ID15: =HK15-IC15 -> 0 | IF15: =ROUNDUP(DR15,0) -> 0 | IG15: =DR15-IF15 -> 0 | IH15: =ROUNDUP(DT15,0) -> 0 | II15: =DT15-IH15 -> 0 | IJ15: =ROUNDUP(DU15,0) -> 0 | IK15: =DU15-IJ15 -> 0 | IL15: =ROUNDUP(DV15,0) -> 0 | IM15: =DV15-IL15 -> 0 | IN15: =ROUNDUP(DX15,0) -> 0 | IO15: =DX15-IN15 -> 0 | IP15: =ROUNDUP(DY15,0) -> 0 | IQ15: =DY15-IP15 -> 0 | IR15: =ROUNDUP(DZ15,0) -> 0 | IS15: =DZ15-IR15 -> 0 | IT15: =ROUNDUP(EB15,0) -> 0 | IU15: =EB15-IT15 -> 0 | IV15: =ROUNDUP(EC15,0) -> 0 | IW15: =EC15-IV15 -> 0
D16: dst.. | M16: =J16*L16 -> 0 | Q16: =N16*P16 -> 0 | S16: =O16 -> 0 | T16: =P16 -> 0 | U16: =R16*T16 -> 0 | V16: =J16+N16-R16 -> 0 | W16: =O16 -> 0 | X16: =P16 -> 0 | Y16: =V16*X16 -> 0 | AC16: =Z16*AB16 -> 0 | AE16: =AA16 -> 0 | AF16: =AB16 -> 0 | AG16: =AD16*AF16 -> 0 | AH16: =V16+Z16-AD16 -> 0 | AI16: =AA16 -> 0 | AJ16: =AB16 -> 0 | AK16: =AH16*AJ16 -> 0 | AO16: =AL16*AN16 -> 0 | AQ16: =AM16 -> 0 | AR16: =AN16 -> 0 | AS16: =AP16*AR16 -> 0 | AT16: =AH16+AL16-AP16 -> 0 | AU16: =AM16 -> 0 | AV16: =AN16 -> 0 | AW16: =AT16*AV16 -> 0 | BA16: =AX16*AZ16 -> 0 | BC16: =AY16 -> 0 | BD16: =AZ16 -> 0 | BE16: =BB16*BD16 -> 0 | BF16: =AT16+AX16-BB16 -> 0 | BG16: =AY16 -> 0 | BH16: =AZ16 -> 0 | BI16: =BF16*BH16 -> 0 | BM16: =BJ16*BL16 -> 0 | BO16: =BK16 -> 0 | BP16: =BL16 -> 0 | BQ16: =BN16*BP16 -> 0 | BR16: =BF16+BJ16-BN16 -> 0 | BS16: =BK16 -> 0 | BT16: =BL16 -> 0 | BU16: =BR16*BT16 -> 0 | BY16: =BV16*BX16 -> 0 | CA16: =BW16 -> 0 | CB16: =BX16 -> 0 | CC16: =BZ16*CB16 -> 0 | CD16: =BR16+BV16-BZ16 -> 0 | CE16: =BW16 -> 0 | CF16: =BX16 -> 0 | CG16: =CD16*CF16 -> 0 | CI16: =CE16 -> 0 | CJ16: =CF16 -> 0 | CK16: =CH16*CJ16 -> 0 | CM16: =CI16 -> 0 | CN16: =CJ16 -> 0 | CO16: =CL16*CN16 -> 0 | CP16: =CD16+CH16-CL16 -> 0 | CQ16: =CI16 -> 0 | CR16: =CJ16 -> 0 | CS16: =CP16*CR16 -> 0 | CU16: =CQ16 -> 0 | CV16: =CR16 -> 0 | CW16: =CT16*CV16 -> 0 | CY16: =CU16 -> 0 | CZ16: =CV16 -> 0 | DA16: =CX16*CZ16 -> 0 | DB16: =CP16+CT16-CX16 -> 0 | DC16: =CU16 -> 0 | DD16: =CV16 -> 0 | DE16: =DB16*DD16 -> 0 | DG16: =DC16 -> 0 | DH16: =DD16 -> 0 | DI16: =DF16*DH16 -> 0 | DK16: =DG16 -> 0 | DL16: =DH16 -> 0 | DM16: =DJ16*DL16 -> 0 | DN16: =DB16+DF16-DJ16 -> 0 | DO16: =DG16 -> 0 | DP16: =DH16 -> 0 | DQ16: =DN16*DP16 -> 0 | DS16: =DO16 -> 0 | DT16: =DP16 -> 0 | DU16: =DR16*DT16 -> 0 | DW16: =DS16 -> 0 | DX16: =DT16 -> 0 | DY16: =DV16*DX16 -> 0 | DZ16: =DN16+DR16-DV16 -> 0 | EA16: =DS16 -> 0 | EB16: =DT16 -> 0 | EC16: =DZ16*EB16 -> 0 | EE16: =EA16 -> 0 | EF16: =EB16 -> 0 | EG16: =ED16*EF16 -> 0 | EI16: =EE16 -> 0 | EJ16: =EF16 -> 0 | EK16: =EH16*EJ16 -> 0 | EL16: =DZ16+ED16-EH16 -> 0 | EM16: =EE16 -> 0 | EN16: =EF16 -> 0 | EO16: =EL16*EN16 -> 0 | EQ16: =EM16 -> 0 | ER16: =EN16 -> 0 | ES16: =EP16*ER16 -> 0 | EU16: =EQ16 -> 0 | EV16: =ER16 -> 0 | EW16: =ET16*EV16 -> 0 | EX16: =EL16+EP16-ET16 -> 0 | EY16: =EQ16 -> 0 | EZ16: =ER16 -> 0 | FA16: =EX16*EZ16 -> 0 | FB16: =N16+Z16+AL16 -> 0 | FC16: =AU16 -> 0 | FD16: =AV16 -> 0 | FE16: =FB16*FD16 -> 0 | FF16: =R16+AD16+AP16 -> 0 | FG16: =FC16 -> 0 | FH16: =FD16 -> 0 | FI16: =FF16*FH16 -> 0 | FJ16: =J16+FB16-FF16 -> 0 | FK16: =FG16 -> 0 | FL16: =FH16 -> 0 | FM16: =FJ16*FL16 -> 0 | FN16: =AX16+BJ16+BV16 -> 0 | FO16: =FK16 -> 0 | FP16: =FL16 -> 0 | FQ16: =FN16*FP16 -> 0 | FR16: =BB16+BN16+BZ16 -> 0 | FS16: =FO16 -> 0 | FT16: =FP16 -> 0 | FU16: =FR16*FT16 -> 0 | FV16: =FJ16+FN16-FR16 -> 0 | FW16: =FS16 -> 0 | FX16: =FT16 -> 0 | FY16: =FV16*FX16 -> 0 | FZ16: =FB16+FN16 -> 0 | GA16: =FW16 -> 0 | GB16: =FX16 -> 0 | GC16: =FZ16*GB16 -> 0 | GD16: =FF16+FR16 -> 0 | GE16: =GA16 -> 0 | GF16: =GB16 -> 0 | GG16: =GD16*GF16 -> 0 | GH16: =J16+FZ16-GD16 -> 0 | GI16: =GE16 -> 0 | GJ16: =GF16 -> 0 | GK16: =GH16*GJ16 -> 0 | GM16: =CH16+CT16+DF16 -> 0 | GN16: =DO16 -> 0 | GO16: =DP16 -> 0 | GP16: =GM16*GO16 -> 0 | GQ16: =CL16+CX16+DJ16 -> 0 | GR16: =GN16 -> 0 | GS16: =GO16 -> 0 | GT16: =GQ16*GS16 -> 0 | GU16: =GH16+GM16-GQ16 -> 0 | GV16: =GR16 -> 0 | GW16: =GS16 -> 0 | GX16: =GU16*GW16 -> 0 | GZ16: =FZ16+GM16 -> 0 | HA16: =GV16 -> 0 | HB16: =GW16 -> 0 | HC16: =GZ16*HB16 -> 0 | HD16: =GD16+GQ16 -> 0 | HE16: =HA16 -> 0 | HF16: =HB16 -> 0 | HG16: =HD16*HF16 -> 0 | HH16: =J16+GZ16-HD16 -> 0 | HI16: =HE16 -> 0 | HJ16: =HF16 -> 0 | HK16: =HH16*HJ16 -> 0 | HM16: =ROUNDUP(GZ16,0) -> 0 | HN16: =GZ16-HM16 -> 0 | HO16: =ROUNDUP(HB16,0) -> 0 | HP16: =HB16-HO16 -> 0 | HQ16: =ROUNDUP(HC16,0) -> 0 | HR16: =HC16-HQ16 -> 0 | HS16: =ROUNDUP(HD16,0) -> 0 | HT16: =HD16-HS16 -> 0 | HU16: =ROUNDUP(HF16,0) -> 0 | HV16: =HF16-HU16 -> 0 | HW16: =ROUNDUP(HG16,0) -> 0 | HX16: =HG16-HW16 -> 0 | HY16: =ROUNDUP(HH16,0) -> 0 | HZ16: =HH16-HY16 -> 0 | IA16: =ROUNDUP(HJ16,0) -> 0 | IB16: =HJ16-IA16 -> 0 | IC16: =ROUNDUP(HK16,0) -> 0 | ID16: =HK16-IC16 -> 0 | IF16: =ROUNDUP(DR16,0) -> 0 | IG16: =DR16-IF16 -> 0 | IH16: =ROUNDUP(DT16,0) -> 0 | II16: =DT16-IH16 -> 0 | IJ16: =ROUNDUP(DU16,0) -> 0 | IK16: =DU16-IJ16 -> 0 | IL16: =ROUNDUP(DV16,0) -> 0 | IM16: =DV16-IL16 -> 0 | IN16: =ROUNDUP(DX16,0) -> 0 | IO16: =DX16-IN16 -> 0 | IP16: =ROUNDUP(DY16,0) -> 0 | IQ16: =DY16-IP16 -> 0 | IR16: =ROUNDUP(DZ16,0) -> 0 | IS16: =DZ16-IR16 -> 0 | IT16: =ROUNDUP(EB16,0) -> 0 | IU16: =EB16-IT16 -> 0 | IV16: =ROUNDUP(EC16,0) -> 0 | IW16: =EC16-IV16 -> 0
D17: TOTAL | M17: =SUM(M14:M16) -> 0 | Q17: =SUM(Q14:Q16) -> 0 | U17: =SUM(U14:U16) -> 0 | Y17: =SUM(Y14:Y16) -> 0 | AC17: =SUM(AC14:AC16) -> 0 | AG17: =SUM(AG14:AG16) -> 0 | AK17: =SUM(AK14:AK16) -> 0 | AO17: =SUM(AO14:AO16) -> 0 | AS17: =SUM(AS14:AS16) -> 0 | AW17: =SUM(AW14:AW16) -> 0 | BA17: =SUM(BA14:BA16) -> 0 | BE17: =SUM(BE14:BE16) -> 0 | BI17: =SUM(BI14:BI16) -> 0 | BM17: =SUM(BM14:BM16) -> 0 | BQ17: =SUM(BQ14:BQ16) -> 0 | BU17: =SUM(BU14:BU16) -> 0 | BY17: =SUM(BY14:BY16) -> 0 | CC17: =SUM(CC14:CC16) -> 0 | CG17: =SUM(CG14:CG16) -> 0 | CK17: =SUM(CK14:CK16) -> 0 | CO17: =SUM(CO14:CO16) -> 0 | CS17: =SUM(CS14:CS16) -> 0 | CW17: =SUM(CW14:CW16) -> 0 | DA17: =SUM(DA14:DA16) -> 0 | DE17: =SUM(DE14:DE16) -> 0 | DI17: =SUM(DI14:DI16) -> 0 | DM17: =SUM(DM14:DM16) -> 0 | DQ17: =SUM(DQ14:DQ16) -> 0 | DU17: =SUM(DU14:DU16) -> 0 | DY17: =SUM(DY14:DY16) -> 0 | EC17: =SUM(EC14:EC16) -> 0 | EG17: =SUM(EG14:EG16) -> 0 | EK17: =SUM(EK14:EK16) -> 0 | EO17: =SUM(EO14:EO16) -> 0 | ES17: =SUM(ES14:ES16) -> 0 | EW17: =SUM(EW14:EW16) -> 0 | FA17: =SUM(FA14:FA16) -> 0
A18: 3 | C18: 5.1.02.01.01.0010 | D18: Bahan-Isi Tabung Gas
B19: CABANG PENDIDIKAN WILAYAH X | C19: 5.1.02.01.01.0010 | D19: 1 | E19: Isi Tabung Gas Elpiji 12 Kg | M19: =J19*L19 -> 0 | Q19: =N19*P19 -> 0 | S19: =O19 -> 0 | T19: =P19 -> 0 | U19: =R19*T19 -> 0 | V19: =J19+N19-R19 -> 0 | W19: =O19 -> 0 | X19: =P19 -> 0 | Y19: =V19*X19 -> 0 | Z19: 1 | AA19: UNIT | AB19: 242000 | AC19: =Z19*AB19 -> 242000 | AD19: 1 | AE19: =AA19 -> UNIT | AF19: =AB19 -> 242000 | AG19: =AD19*AF19 -> 242000 | AH19: =V19+Z19-AD19 -> 0 | AI19: =AA19 -> UNIT | AJ19: =AB19 -> 242000 | AK19: =AH19*AJ19 -> 0 | AM19: =AI19 -> UNIT | AN19: =AJ19 -> 242000 | AO19: =AL19*AN19 -> 0 | AQ19: =AM19 -> UNIT | AR19: =AN19 -> 242000 | AS19: =AP19*AR19 -> 0 | AT19: =AH19+AL19-AP19 -> 0 | AU19: =AM19 -> UNIT | AV19: =AN19 -> 242000 | AW19: =AT19*AV19 -> 0 | AX19: 1 | AY19: UNIT | AZ19: 242000 | BA19: =AX19*AZ19 -> 242000 | BB19: 1 | BC19: UNIT | BD19: 242000 | BE19: =BB19*BD19 -> 242000 | BF19: 0 | BG19: UNIT | BH19: 242000 | BI19: =BF19*BH19 -> 0 | BK19: =BG19 -> UNIT | BL19: =BH19 -> 242000 | BM19: =BJ19*BL19 -> 0 | BO19: =BK19 -> UNIT | BP19: =BL19 -> 242000 | BQ19: =BN19*BP19 -> 0 | BR19: =BF19+BJ19-BN19 -> 0 | BS19: =BK19 -> UNIT | BT19: =BL19 -> 242000 | BU19: =BR19*BT19 -> 0 | BV19: 1 | BW19: =BS19 -> UNIT | BX19: =BT19 -> 242000 | BY19: =BV19*BX19 -> 242000 | BZ19: 1 | CA19: =BW19 -> UNIT | CB19: =BX19 -> 242000 | CC19: =BZ19*CB19 -> 242000 | CD19: =BR19+BV19-BZ19 -> 0 | CE19: =BW19 -> UNIT | CF19: =BX19 -> 242000 | CG19: =CD19*CF19 -> 0 | CI19: =CE19 -> UNIT | CJ19: =CF19 -> 242000 | CK19: =CH19*CJ19 -> 0 | CM19: =CI19 -> UNIT | CN19: =CJ19 -> 242000 | CO19: =CL19*CN19 -> 0 | CP19: =CD19+CH19-CL19 -> 0 | CQ19: =CI19 -> UNIT | CR19: =CJ19 -> 242000 | CS19: =CP19*CR19 -> 0 | CT19: 1 | CU19: =CQ19 -> UNIT | CV19: =CR19 -> 242000 | CW19: =CT19*CV19 -> 242000 | CX19: 1 | CY19: =CU19 -> UNIT | CZ19: =CV19 -> 242000 | DA19: =CX19*CZ19 -> 242000 | DB19: =CP19+CT19-CX19 -> 0 | DC19: =CU19 -> UNIT | DD19: =CV19 -> 242000 | DE19: =DB19*DD19 -> 0 | DG19: =DC19 -> UNIT | DH19: =DD19 -> 242000 | DI19: =DF19*DH19 -> 0 | DK19: =DG19 -> UNIT | DL19: =DH19 -> 242000 | DM19: =DJ19*DL19 -> 0 | DN19: =DB19+DF19-DJ19 -> 0 | DO19: =DG19 -> UNIT | DP19: =DH19 -> 242000 | DQ19: =DN19*DP19 -> 0 | DR19: 1 | DS19: =DO19 -> UNIT | DT19: =DP19 -> 242000 | DU19: =DR19*DT19 -> 242000 | DV19: 1 | DW19: =DS19 -> UNIT | DX19: =DT19 -> 242000 | DY19: =DV19*DX19 -> 242000 | DZ19: =DN19+DR19-DV19 -> 0 | EA19: =DS19 -> UNIT | EB19: =DT19 -> 242000 | EC19: =DZ19*EB19 -> 0 | EE19: =EA19 -> UNIT | EF19: =EB19 -> 242000 | EG19: =ED19*EF19 -> 0 | EI19: =EE19 -> UNIT | EJ19: =EF19 -> 242000 | EK19: =EH19*EJ19 -> 0 | EL19: =DZ19+ED19-EH19 -> 0 | EM19: =EE19 -> UNIT | EN19: =EF19 -> 242000 | EO19: =EL19*EN19 -> 0 | EP19: 1 | EQ19: =EM19 -> UNIT | ER19: =EN19 -> 242000 | ES19: =EP19*ER19 -> 242000 | ET19: 1 | EU19: =EQ19 -> UNIT | EV19: =ER19 -> 242000 | EW19: =ET19*EV19 -> 242000 | EX19: =EL19+EP19-ET19 -> 0 | EY19: =EQ19 -> UNIT | EZ19: =ER19 -> 242000 | FA19: =EX19*EZ19 -> 0 | FB19: =N19+Z19+AL19 -> 1 | FC19: =AU19 -> UNIT | FD19: =AV19 -> 242000 | FE19: =FB19*FD19 -> 242000 | FF19: =R19+AD19+AP19 -> 1 | FG19: =FC19 -> UNIT | FH19: =FD19 -> 242000 | FI19: =FF19*FH19 -> 242000 | FJ19: =J19+FB19-FF19 -> 0 | FK19: =FG19 -> UNIT | FL19: =FH19 -> 242000 | FM19: =FJ19*FL19 -> 0 | FN19: =AX19+BJ19+BV19 -> 2 | FO19: =FK19 -> UNIT | FP19: =FL19 -> 242000 | FQ19: =FN19*FP19 -> 484000 | FR19: =BB19+BN19+BZ19 -> 2 | FS19: =FO19 -> UNIT | FT19: =FP19 -> 242000 | FU19: =FR19*FT19 -> 484000 | FV19: =FJ19+FN19-FR19 -> 0 | FW19: =FS19 -> UNIT | FX19: =FT19 -> 242000 | FY19: =FV19*FX19 -> 0 | FZ19: =FB19+FN19 -> 3 | GA19: =FW19 -> UNIT | GB19: =FX19 -> 242000 | GC19: =FZ19*GB19 -> 726000 | GD19: =FF19+FR19 -> 3 | GE19: =GA19 -> UNIT | GF19: =GB19 -> 242000 | GG19: =GD19*GF19 -> 726000 | GH19: =J19+FZ19-GD19 -> 0 | GI19: =GE19 -> UNIT | GJ19: =GF19 -> 242000 | GK19: =GH19*GJ19 -> 0 | GM19: =CH19+CT19+DF19 -> 1 | GN19: =DO19 -> UNIT | GO19: =DP19 -> 242000 | GP19: =GM19*GO19 -> 242000 | GQ19: =CL19+CX19+DJ19 -> 1 | GR19: =GN19 -> UNIT | GS19: =GO19 -> 242000 | GT19: =GQ19*GS19 -> 242000 | GU19: =GH19+GM19-GQ19 -> 0 | GV19: =GR19 -> UNIT | GW19: =GS19 -> 242000 | GX19: =GU19*GW19 -> 0 | GZ19: =FZ19+GM19 -> 4 | HA19: =GV19 -> UNIT | HB19: =GW19 -> 242000 | HC19: =GZ19*HB19 -> 968000 | HD19: =GD19+GQ19 -> 4 | HE19: =HA19 -> UNIT | HF19: =HB19 -> 242000 | HG19: =HD19*HF19 -> 968000 | HH19: =J19+GZ19-HD19 -> 0 | HI19: =HE19 -> UNIT | HJ19: =HF19 -> 242000 | HK19: =HH19*HJ19 -> 0 | HL19: TIDAK | HM19: =ROUNDUP(GZ19,0) -> 4 | HN19: =GZ19-HM19 -> 0 | HO19: =ROUNDUP(HB19,0) -> 242000 | HP19: =HB19-HO19 -> 0 | HQ19: =ROUNDUP(HC19,0) -> 968000 | HR19: =HC19-HQ19 -> 0 | HS19: =ROUNDUP(HD19,0) -> 4 | HT19: =HD19-HS19 -> 0 | HU19: =ROUNDUP(HF19,0) -> 242000 | HV19: =HF19-HU19 -> 0 | HW19: =ROUNDUP(HG19,0) -> 968000 | HX19: =HG19-HW19 -> 0 | HY19: =ROUNDUP(HH19,0) -> 0 | HZ19: =HH19-HY19 -> 0 | IA19: =ROUNDUP(HJ19,0) -> 242000 | IB19: =HJ19-IA19 -> 0 | IC19: =ROUNDUP(HK19,0) -> 0 | ID19: =HK19-IC19 -> 0 | IF19: =ROUNDUP(DR19,0) -> 1 | IG19: =DR19-IF19 -> 0 | IH19: =ROUNDUP(DT19,0) -> 242000 | II19: =DT19-IH19 -> 0 | IJ19: =ROUNDUP(DU19,0) -> 242000 | IK19: =DU19-IJ19 -> 0 | IL19: =ROUNDUP(DV19,0) -> 1 | IM19: =DV19-IL19 -> 0 | IN19: =ROUNDUP(DX19,0) -> 242000 | IO19: =DX19-IN19 -> 0 | IP19: =ROUNDUP(DY19,0) -> 242000 | IQ19: =DY19-IP19 -> 0 | IR19: =ROUNDUP(DZ19,0) -> 0 | IS19: =DZ19-IR19 -> 0 | IT19: =ROUNDUP(EB19,0) -> 242000 | IU19: =EB19-IT19 -> 0 | IV19: =ROUNDUP(EC19,0) -> 0 | IW19: =EC19-IV19 -> 0 | IY19: =DR19+GZ19 -> 5 | IZ19: =DS19 -> UNIT | JA19: =DT19 -> 242000 | JB19: =IY19*JA19 -> 1210000 | JC19: =DV19+HD19 -> 5 | JD19: =IZ19 -> UNIT | JE19: =JA19 -> 242000 | JF19: =JC19*JE19 -> 1210000 | JG19: =J19+IY19-JC19 -> 0 | JH19: =JD19 -> UNIT | JI19: =JE19 -> 242000 | JJ19: =JG19*JI19 -> 0
D20: 2 | CI20: =CE20 -> 0 | CJ20: =CF20 -> 0 | CK20: =CH20*CJ20 -> 0 | CM20: =CI20 -> 0 | CN20: =CJ20 -> 0 | CO20: =CL20*CN20 -> 0 | CP20: =CD20+CH20-CL20 -> 0 | CQ20: =CI20 -> 0 | CR20: =CJ20 -> 0 | CS20: =CP20*CR20 -> 0 | CU20: =CQ20 -> 0 | CV20: =CR20 -> 0 | CW20: =CT20*CV20 -> 0 | CY20: =CU20 -> 0 | CZ20: =CV20 -> 0 | DA20: =CX20*CZ20 -> 0 | DB20: =CP20+CT20-CX20 -> 0 | DC20: =CU20 -> 0 | DD20: =CV20 -> 0 | DE20: =DB20*DD20 -> 0 | DG20: =DC20 -> 0 | DH20: =DD20 -> 0 | DI20: =DF20*DH20 -> 0 | DK20: =DG20 -> 0 | DL20: =DH20 -> 0 | DM20: =DJ20*DL20 -> 0 | DN20: =DB20+DF20-DJ20 -> 0 | DO20: =DG20 -> 0 | DP20: =DH20 -> 0 | DQ20: =DN20*DP20 -> 0 | DS20: =DO20 -> 0 | DT20: =DP20 -> 0 | DU20: =DR20*DT20 -> 0 | DW20: =DS20 -> 0 | DX20: =DT20 -> 0 | DY20: =DV20*DX20 -> 0 | DZ20: =DN20+DR20-DV20 -> 0 | EA20: =DS20 -> 0 | EB20: =DT20 -> 0 | EC20: =DZ20*EB20 -> 0 | EE20: =EA20 -> 0 | EF20: =EB20 -> 0 | EG20: =ED20*EF20 -> 0 | EI20: =EE20 -> 0 | EJ20: =EF20 -> 0 | EK20: =EH20*EJ20 -> 0 | EL20: =DZ20+ED20-EH20 -> 0 | EM20: =EE20 -> 0 | EN20: =EF20 -> 0 | EO20: =EL20*EN20 -> 0 | EQ20: =EM20 -> 0 | ER20: =EN20 -> 0 | ES20: =EP20*ER20 -> 0 | EU20: =EQ20 -> 0 | EV20: =ER20 -> 0 | EW20: =ET20*EV20 -> 0 | EX20: =EL20+EP20-ET20 -> 0 | EY20: =EQ20 -> 0 | EZ20: =ER20 -> 0 | FA20: =EX20*EZ20 -> 0 | FB20: =N20+Z20+AL20 -> 0 | FC20: =AU20 -> 0 | FD20: =AV20 -> 0 | FE20: =FB20*FD20 -> 0 | FF20: =R20+AD20+AP20 -> 0 | FG20: =FC20 -> 0 | FH20: =FD20 -> 0 | FI20: =FF20*FH20 -> 0 | FJ20: =J20+FB20-FF20 -> 0 | FK20: =FG20 -> 0 | FL20: =FH20 -> 0 | FM20: =FJ20*FL20 -> 0 | FN20: =AX20+BJ20+BV20 -> 0 | FO20: =FK20 -> 0 | FP20: =FL20 -> 0 | FQ20: =FN20*FP20 -> 0 | FR20: =BB20+BN20+BZ20 -> 0 | FS20: =FO20 -> 0 | FT20: =FP20 -> 0 | FU20: =FR20*FT20 -> 0 | FV20: =FJ20+FN20-FR20 -> 0 | FW20: =FS20 -> 0 | FX20: =FT20 -> 0 | FY20: =FV20*FX20 -> 0 | FZ20: =FB20+FN20 -> 0 | GA20: =FW20 -> 0 | GB20: =FX20 -> 0 | GC20: =FZ20*GB20 -> 0 | GD20: =FF20+FR20 -> 0 | GE20: =GA20 -> 0 | GF20: =GB20 -> 0 | GG20: =GD20*GF20 -> 0 | GH20: =J20+FZ20-GD20 -> 0 | GI20: =GE20 -> 0 | GJ20: =GF20 -> 0 | GK20: =GH20*GJ20 -> 0 | GM20: =CH20+CT20+DF20 -> 0 | GN20: =DO20 -> 0 | GO20: =DP20 -> 0 | GP20: =GM20*GO20 -> 0 | GQ20: =CL20+CX20+DJ20 -> 0 | GR20: =GN20 -> 0 | GS20: =GO20 -> 0 | GT20: =GQ20*GS20 -> 0 | GU20: =GH20+GM20-GQ20 -> 0 | GV20: =GR20 -> 0 | GW20: =GS20 -> 0 | GX20: =GU20*GW20 -> 0 | GZ20: =FZ20+GM20 -> 0 | HA20: =GV20 -> 0 | HB20: =GW20 -> 0 | HC20: =GZ20*HB20 -> 0 | HD20: =GD20+GQ20 -> 0 | HE20: =HA20 -> 0 | HF20: =HB20 -> 0 | HG20: =HD20*HF20 -> 0 | HH20: =J20+GZ20-HD20 -> 0 | HI20: =HE20 -> 0 | HJ20: =HF20 -> 0 | HK20: =HH20*HJ20 -> 0 | HM20: =ROUNDUP(GZ20,0) -> 0 | HN20: =GZ20-HM20 -> 0 | HO20: =ROUNDUP(HB20,0) -> 0 | HP20: =HB20-HO20 -> 0 | HQ20: =ROUNDUP(HC20,0) -> 0 | HR20: =HC20-HQ20 -> 0 | HS20: =ROUNDUP(HD20,0) -> 0 | HT20: =HD20-HS20 -> 0 | HU20: =ROUNDUP(HF20,0) -> 0 | HV20: =HF20-HU20 -> 0 | HW20: =ROUNDUP(HG20,0) -> 0 | HX20: =HG20-HW20 -> 0 | HY20: =ROUNDUP(HH20,0) -> 0 | HZ20: =HH20-HY20 -> 0 | IA20: =ROUNDUP(HJ20,0) -> 0 | IB20: =HJ20-IA20 -> 0 | IC20: =ROUNDUP(HK20,0) -> 0 | ID20: =HK20-IC20 -> 0 | IF20: =ROUNDUP(DR20,0) -> 0 | IG20: =DR20-IF20 -> 0 | IH20: =ROUNDUP(DT20,0) -> 0 | II20: =DT20-IH20 -> 0 | IJ20: =ROUNDUP(DU20,0) -> 0 | IK20: =DU20-IJ20 -> 0 | IL20: =ROUNDUP(DV20,0) -> 0 | IM20: =DV20-IL20 -> 0 | IN20: =ROUNDUP(DX20,0) -> 0 | IO20: =DX20-IN20 -> 0 | IP20: =ROUNDUP(DY20,0) -> 0 | IQ20: =DY20-IP20 -> 0 | IR20: =ROUNDUP(DZ20,0) -> 0 | IS20: =DZ20-IR20 -> 0 | IT20: =ROUNDUP(EB20,0) -> 0 | IU20: =EB20-IT20 -> 0 | IV20: =ROUNDUP(EC20,0) -> 0 | IW20: =EC20-IV20 -> 0
D21: dst.. | CI21: =CE21 -> 0 | CJ21: =CF21 -> 0 | CK21: =CH21*CJ21 -> 0 | CM21: =CI21 -> 0 | CN21: =CJ21 -> 0 | CO21: =CL21*CN21 -> 0 | CP21: =CD21+CH21-CL21 -> 0 | CQ21: =CI21 -> 0 | CR21: =CJ21 -> 0 | CS21: =CP21*CR21 -> 0 | CU21: =CQ21 -> 0 | CV21: =CR21 -> 0 | CW21: =CT21*CV21 -> 0 | CY21: =CU21 -> 0 | CZ21: =CV21 -> 0 | DA21: =CX21*CZ21 -> 0 | DB21: =CP21+CT21-CX21 -> 0 | DC21: =CU21 -> 0 | DD21: =CV21 -> 0 | DE21: =DB21*DD21 -> 0 | DG21: =DC21 -> 0 | DH21: =DD21 -> 0 | DI21: =DF21*DH21 -> 0 | DK21: =DG21 -> 0 | DL21: =DH21 -> 0 | DM21: =DJ21*DL21 -> 0 | DN21: =DB21+DF21-DJ21 -> 0 | DO21: =DG21 -> 0 | DP21: =DH21 -> 0 | DQ21: =DN21*DP21 -> 0 | DS21: =DO21 -> 0 | DT21: =DP21 -> 0 | DU21: =DR21*DT21 -> 0 | DW21: =DS21 -> 0 | DX21: =DT21 -> 0 | DY21: =DV21*DX21 -> 0 | DZ21: =DN21+DR21-DV21 -> 0 | EA21: =DS21 -> 0 | EB21: =DT21 -> 0 | EC21: =DZ21*EB21 -> 0 | EE21: =EA21 -> 0 | EF21: =EB21 -> 0 | EG21: =ED21*EF21 -> 0 | EI21: =EE21 -> 0 | EJ21: =EF21 -> 0 | EK21: =EH21*EJ21 -> 0 | EL21: =DZ21+ED21-EH21 -> 0 | EM21: =EE21 -> 0 | EN21: =EF21 -> 0 | EO21: =EL21*EN21 -> 0 | EQ21: =EM21 -> 0 | ER21: =EN21 -> 0 | ES21: =EP21*ER21 -> 0 | EU21: =EQ21 -> 0 | EV21: =ER21 -> 0 | EW21: =ET21*EV21 -> 0 | EX21: =EL21+EP21-ET21 -> 0 | EY21: =EQ21 -> 0 | EZ21: =ER21 -> 0 | FA21: =EX21*EZ21 -> 0 | FB21: =N21+Z21+AL21 -> 0 | FC21: =AU21 -> 0 | FD21: =AV21 -> 0 | FE21: =FB21*FD21 -> 0 | FF21: =R21+AD21+AP21 -> 0 | FG21: =FC21 -> 0 | FH21: =FD21 -> 0 | FI21: =FF21*FH21 -> 0 | FJ21: =J21+FB21-FF21 -> 0 | FK21: =FG21 -> 0 | FL21: =FH21 -> 0 | FM21: =FJ21*FL21 -> 0 | FN21: =AX21+BJ21+BV21 -> 0 | FO21: =FK21 -> 0 | FP21: =FL21 -> 0 | FQ21: =FN21*FP21 -> 0 | FR21: =BB21+BN21+BZ21 -> 0 | FS21: =FO21 -> 0 | FT21: =FP21 -> 0 | FU21: =FR21*FT21 -> 0 | FV21: =FJ21+FN21-FR21 -> 0 | FW21: =FS21 -> 0 | FX21: =FT21 -> 0 | FY21: =FV21*FX21 -> 0 | FZ21: =FB21+FN21 -> 0 | GA21: =FW21 -> 0 | GB21: =FX21 -> 0 | GC21: =FZ21*GB21 -> 0 | GD21: =FF21+FR21 -> 0 | GE21: =GA21 -> 0 | GF21: =GB21 -> 0 | GG21: =GD21*GF21 -> 0 | GH21: =J21+FZ21-GD21 -> 0 | GI21: =GE21 -> 0 | GJ21: =GF21 -> 0 | GK21: =GH21*GJ21 -> 0 | GM21: =CH21+CT21+DF21 -> 0 | GN21: =DO21 -> 0 | GO21: =DP21 -> 0 | GP21: =GM21*GO21 -> 0 | GQ21: =CL21+CX21+DJ21 -> 0 | GR21: =GN21 -> 0 | GS21: =GO21 -> 0 | GT21: =GQ21*GS21 -> 0 | GU21: =GH21+GM21-GQ21 -> 0 | GV21: =GR21 -> 0 | GW21: =GS21 -> 0 | GX21: =GU21*GW21 -> 0 | GZ21: =FZ21+GM21 -> 0 | HA21: =GV21 -> 0 | HB21: =GW21 -> 0 | HC21: =GZ21*HB21 -> 0 | HD21: =GD21+GQ21 -> 0 | HE21: =HA21 -> 0 | HF21: =HB21 -> 0 | HG21: =HD21*HF21 -> 0 | HH21: =J21+GZ21-HD21 -> 0 | HI21: =HE21 -> 0 | HJ21: =HF21 -> 0 | HK21: =HH21*HJ21 -> 0 | HM21: =ROUNDUP(GZ21,0) -> 0 | HN21: =GZ21-HM21 -> 0 | HO21: =ROUNDUP(HB21,0) -> 0 | HP21: =HB21-HO21 -> 0 | HQ21: =ROUNDUP(HC21,0) -> 0 | HR21: =HC21-HQ21 -> 0 | HS21: =ROUNDUP(HD21,0) -> 0 | HT21: =HD21-HS21 -> 0 | HU21: =ROUNDUP(HF21,0) -> 0 | HV21: =HF21-HU21 -> 0 | HW21: =ROUNDUP(HG21,0) -> 0 | HX21: =HG21-HW21 -> 0 | HY21: =ROUNDUP(HH21,0) -> 0 | HZ21: =HH21-HY21 -> 0 | IA21: =ROUNDUP(HJ21,0) -> 0 | IB21: =HJ21-IA21 -> 0 | IC21: =ROUNDUP(HK21,0) -> 0 | ID21: =HK21-IC21 -> 0 | IF21: =ROUNDUP(DR21,0) -> 0 | IG21: =DR21-IF21 -> 0 | IH21: =ROUNDUP(DT21,0) -> 0 | II21: =DT21-IH21 -> 0 | IJ21: =ROUNDUP(DU21,0) -> 0 | IK21: =DU21-IJ21 -> 0 | IL21: =ROUNDUP(DV21,0) -> 0 | IM21: =DV21-IL21 -> 0 | IN21: =ROUNDUP(DX21,0) -> 0 | IO21: =DX21-IN21 -> 0 | IP21: =ROUNDUP(DY21,0) -> 0 | IQ21: =DY21-IP21 -> 0 | IR21: =ROUNDUP(DZ21,0) -> 0 | IS21: =DZ21-IR21 -> 0 | IT21: =ROUNDUP(EB21,0) -> 0 | IU21: =EB21-IT21 -> 0 | IV21: =ROUNDUP(EC21,0) -> 0 | IW21: =EC21-IV21 -> 0
D22: TOTAL | M22: =SUM(M19:M19) -> 0 | Q22: =SUM(Q19:Q19) -> 0 | U22: =SUM(U19:U19) -> 0 | Y22: =SUM(Y19:Y19) -> 0 | AC22: =SUM(AC19:AC19) -> 242000 | AG22: =SUM(AG19:AG19) -> 242000 | AK22: =SUM(AK19:AK19) -> 0 | AO22: =SUM(AO19:AO19) -> 0 | AS22: =SUM(AS19:AS19) -> 0 | AW22: =SUM(AW19:AW19) -> 0 | BA22: =SUM(BA19:BA19) -> 242000 | BE22: =SUM(BE19:BE19) -> 242000 | BI22: =SUM(BI19:BI19) -> 0 | BM22: =SUM(BM19:BM19) -> 0 | BQ22: =SUM(BQ19:BQ19) -> 0 | BU22: =SUM(BU19:BU19) -> 0 | BY22: =SUM(BY19:BY19) -> 242000 | CC22: =SUM(CC19:CC19) -> 242000 | CG22: =SUM(CG19:CG19) -> 0 | CK22: =SUM(CK19:CK19) -> 0 | CO22: =SUM(CO19:CO19) -> 0 | CS22: =SUM(CS19:CS19) -> 0 | CW22: =SUM(CW19:CW19) -> 242000 | DA22: =SUM(DA19:DA19) -> 242000 | DE22: =SUM(DE19:DE19) -> 0 | DI22: =SUM(DI19:DI19) -> 0 | DM22: =SUM(DM19:DM19) -> 0 | DQ22: =SUM(DQ19:DQ19) -> 0 | DU22: =SUM(DU19:DU19) -> 242000 | DY22: =SUM(DY19:DY19) -> 242000 | EC22: =SUM(EC19:EC19) -> 0 | EG22: =SUM(EG19:EG19) -> 0 | EK22: =SUM(EK19:EK19) -> 0 | EO22: =SUM(EO19:EO19) -> 0 | ES22: =SUM(ES19:ES19) -> 242000 | EW22: =SUM(EW19:EW19) -> 242000 | FA22: =SUM(FA19:FA19) -> 0
A23: 4 | C23: 5.1.02.01.01.0012 | D23: Bahan-Bahan Lainnya
D24: 1 | M24: =J24*L24 -> 0 | Q24: =N24*P24 -> 0 | S24: =O24 -> 0 | T24: =P24 -> 0 | U24: =R24*T24 -> 0 | V24: =J24+N24-R24 -> 0 | W24: =O24 -> 0 | X24: =P24 -> 0 | Y24: =V24*X24 -> 0 | AC24: =Z24*AB24 -> 0 | AE24: =AA24 -> 0 | AF24: =AB24 -> 0 | AG24: =AD24*AF24 -> 0 | AH24: =V24+Z24-AD24 -> 0 | AI24: =AA24 -> 0 | AJ24: =AB24 -> 0 | AK24: =AH24*AJ24 -> 0 | AO24: =AL24*AN24 -> 0 | AQ24: =AM24 -> 0 | AR24: =AN24 -> 0 | AS24: =AP24*AR24 -> 0 | AT24: =AH24+AL24-AP24 -> 0 | AU24: =AM24 -> 0 | AV24: =AN24 -> 0 | AW24: =AT24*AV24 -> 0 | BA24: =AX24*AZ24 -> 0 | BC24: =AY24 -> 0 | BD24: =AZ24 -> 0 | BE24: =BB24*BD24 -> 0 | BF24: =AT24+AX24-BB24 -> 0 | BG24: =AY24 -> 0 | BH24: =AZ24 -> 0 | BI24: =BF24*BH24 -> 0 | BM24: =BJ24*BL24 -> 0 | BO24: =BK24 -> 0 | BP24: =BL24 -> 0 | BQ24: =BN24*BP24 -> 0 | BR24: =BF24+BJ24-BN24 -> 0 | BS24: =BK24 -> 0 | BT24: =BL24 -> 0 | BU24: =BR24*BT24 -> 0 | BY24: =BV24*BX24 -> 0 | CA24: =BW24 -> 0 | CB24: =BX24 -> 0 | CC24: =BZ24*CB24 -> 0 | CD24: =BR24+BV24-BZ24 -> 0 | CE24: =BW24 -> 0 | CF24: =BX24 -> 0 | CG24: =CD24*CF24 -> 0 | CI24: =CE24 -> 0 | CJ24: =CF24 -> 0 | CK24: =CH24*CJ24 -> 0 | CM24: =CI24 -> 0 | CN24: =CJ24 -> 0 | CO24: =CL24*CN24 -> 0 | CP24: =CD24+CH24-CL24 -> 0 | CQ24: =CI24 -> 0 | CR24: =CJ24 -> 0 | CS24: =CP24*CR24 -> 0 | CU24: =CQ24 -> 0 | CV24: =CR24 -> 0 | CW24: =CT24*CV24 -> 0 | CY24: =CU24 -> 0 | CZ24: =CV24 -> 0 | DA24: =CX24*CZ24 -> 0 | DB24: =CP24+CT24-CX24 -> 0 | DC24: =CU24 -> 0 | DD24: =CV24 -> 0 | DE24: =DB24*DD24 -> 0 | DG24: =DC24 -> 0 | DH24: =DD24 -> 0 | DI24: =DF24*DH24 -> 0 | DK24: =DG24 -> 0 | DL24: =DH24 -> 0 | DM24: =DJ24*DL24 -> 0 | DN24: =DB24+DF24-DJ24 -> 0 | DO24: =DG24 -> 0 | DP24: =DH24 -> 0 | DQ24: =DN24*DP24 -> 0 | DS24: =DO24 -> 0 | DT24: =DP24 -> 0 | DU24: =DR24*DT24 -> 0 | DW24: =DS24 -> 0 | DX24: =DT24 -> 0 | DY24: =DV24*DX24 -> 0 | DZ24: =DN24+DR24-DV24 -> 0 | EA24: =DS24 -> 0 | EB24: =DT24 -> 0 | EC24: =DZ24*EB24 -> 0 | EE24: =EA24 -> 0 | EF24: =EB24 -> 0 | EG24: =ED24*EF24 -> 0 | EI24: =EE24 -> 0 | EJ24: =EF24 -> 0 | EK24: =EH24*EJ24 -> 0 | EL24: =DZ24+ED24-EH24 -> 0 | EM24: =EE24 -> 0 | EN24: =EF24 -> 0 | EO24: =EL24*EN24 -> 0 | EQ24: =EM24 -> 0 | ER24: =EN24 -> 0 | ES24: =EP24*ER24 -> 0 | EU24: =EQ24 -> 0 | EV24: =ER24 -> 0 | EW24: =ET24*EV24 -> 0 | EX24: =EL24+EP24-ET24 -> 0 | EY24: =EQ24 -> 0 | EZ24: =ER24 -> 0 | FA24: =EX24*EZ24 -> 0 | FB24: =N24+Z24+AL24 -> 0 | FC24: =AU24 -> 0 | FD24: =AV24 -> 0 | FE24: =FB24*FD24 -> 0 | FF24: =R24+AD24+AP24 -> 0 | FG24: =FC24 -> 0 | FH24: =FD24 -> 0 | FI24: =FF24*FH24 -> 0 | FJ24: =J24+FB24-FF24 -> 0 | FK24: =FG24 -> 0 | FL24: =FH24 -> 0 | FM24: =FJ24*FL24 -> 0 | FN24: =AX24+BJ24+BV24 -> 0 | FO24: =FK24 -> 0 | FP24: =FL24 -> 0 | FQ24: =FN24*FP24 -> 0 | FR24: =BB24+BN24+BZ24 -> 0 | FS24: =FO24 -> 0 | FT24: =FP24 -> 0 | FU24: =FR24*FT24 -> 0 | FV24: =FJ24+FN24-FR24 -> 0 | FW24: =FS24 -> 0 | FX24: =FT24 -> 0 | FY24: =FV24*FX24 -> 0 | FZ24: =FB24+FN24 -> 0 | GA24: =FW24 -> 0 | GB24: =FX24 -> 0 | GC24: =FZ24*GB24 -> 0 | GD24: =FF24+FR24 -> 0 | GE24: =GA24 -> 0 | GF24: =GB24 -> 0 | GG24: =GD24*GF24 -> 0 | GH24: =J24+FZ24-GD24 -> 0 | GI24: =GE24 -> 0 | GJ24: =GF24 -> 0 | GK24: =GH24*GJ24 -> 0 | GM24: =CH24+CT24+DF24 -> 0 | GN24: =DO24 -> 0 | GO24: =DP24 -> 0 | GP24: =GM24*GO24 -> 0 | GQ24: =CL24+CX24+DJ24 -> 0 | GR24: =GN24 -> 0 | GS24: =GO24 -> 0 | GT24: =GQ24*GS24 -> 0 | GU24: =GH24+GM24-GQ24 -> 0 | GV24: =GR24 -> 0 | GW24: =GS24 -> 0 | GX24: =GU24*GW24 -> 0 | GZ24: =FZ24+GM24 -> 0 | HA24: =GV24 -> 0 | HB24: =GW24 -> 0 | HC24: =GZ24*HB24 -> 0 | HD24: =GD24+GQ24 -> 0 | HE24: =HA24 -> 0 | HF24: =HB24 -> 0 | HG24: =HD24*HF24 -> 0 | HH24: =J24+GZ24-HD24 -> 0 | HI24: =HE24 -> 0 | HJ24: =HF24 -> 0 | HK24: =HH24*HJ24 -> 0 | HM24: =ROUNDUP(GZ24,0) -> 0 | HN24: =GZ24-HM24 -> 0 | HO24: =ROUNDUP(HB24,0) -> 0 | HP24: =HB24-HO24 -> 0 | HQ24: =ROUNDUP(HC24,0) -> 0 | HR24: =HC24-HQ24 -> 0 | HS24: =ROUNDUP(HD24,0) -> 0 | HT24: =HD24-HS24 -> 0 | HU24: =ROUNDUP(HF24,0) -> 0 | HV24: =HF24-HU24 -> 0 | HW24: =ROUNDUP(HG24,0) -> 0 | HX24: =HG24-HW24 -> 0 | HY24: =ROUNDUP(HH24,0) -> 0 | HZ24: =HH24-HY24 -> 0 | IA24: =ROUNDUP(HJ24,0) -> 0 | IB24: =HJ24-IA24 -> 0 | IC24: =ROUNDUP(HK24,0) -> 0 | ID24: =HK24-IC24 -> 0 | IF24: =ROUNDUP(DR24,0) -> 0 | IG24: =DR24-IF24 -> 0 | IH24: =ROUNDUP(DT24,0) -> 0 | II24: =DT24-IH24 -> 0 | IJ24: =ROUNDUP(DU24,0) -> 0 | IK24: =DU24-IJ24 -> 0 | IL24: =ROUNDUP(DV24,0) -> 0 | IM24: =DV24-IL24 -> 0 | IN24: =ROUNDUP(DX24,0) -> 0 | IO24: =DX24-IN24 -> 0 | IP24: =ROUNDUP(DY24,0) -> 0 | IQ24: =DY24-IP24 -> 0 | IR24: =ROUNDUP(DZ24,0) -> 0 | IS24: =DZ24-IR24 -> 0 | IT24: =ROUNDUP(EB24,0) -> 0 | IU24: =EB24-IT24 -> 0 | IV24: =ROUNDUP(EC24,0) -> 0 | IW24: =EC24-IV24 -> 0
